Workbook

Sheet Tankers
A1: nation | B1: type | C1: model
A2: {=_xlfn.UNIQUE(_xlfn._xlws.FILTER(Specifications!A2:C100, (Specifications!A2:A100<>"") * (Specifications!B2:B100<>"") * (Specifications!C2:C100<>"")))} -> Australia | B2: A330 MRTT | C2: KC-30A
A3: USA | B3: KC-10 | C3: A
A4: Omega | B4: KC-10 | C4: KDC-10B
A5: Omega | B5: KDC-10 | C5: B
A6: Malaysia | B6: A400 | C6: M
A7: Singapore | B7: A330 MRTT | C7: A330 MRTT
A8: France | B8: A330 MRTT | C8: Phénix
A9: South Korea | B9: A330 MRTT | C9: KC-330
A10: MMF | B10: A330 MRTT | C10: KC-30M
A11: USA | B11: KC-135 | C11: R
A12: MSM | B12: KC-135 | C12: R
A13: USA | B13: KC-135 | C13: T
A14: USA | B14: KC-46 | C14: A
A15: France | B15: C-135 | C15: FR

Sheet Receivers
A1: nation | B1: type | C1: model
A2: {=_xlfn.UNIQUE(_xlfn._xlws.FILTER(Specifications!D2:F100, (Specifications!D2:D100<>"") * (Specifications!E2:E100<>"") * (Specifications!F2:F100<>"")))} -> Australia | B2: C-17 | C2: A
A3: Australia | B3: E-7 | C3: A
A4: Australia | B4: EA-18 | C4: G
A5: Australia | B5: F/A-18 | C5: A
A6: Australia | B6: F35 | C6: A
A7: Australia | B7: A330 MRTT | C7: KC-30A
A8: Australia | B8: P-8 | C8: A
A9: USA | B9: B-1 | C9: B
A10: USA | B10: A-10 | C10: C
A11: Japan | B11: F-15 | C11: J
A12: Japan | B12: F-15 | C12: DJ
A13: Japan | B13: F-15 | C13: K
A14: Singapore | B14: F-15 | C14: SG
... A79: Australia | B79: F/A-18 | C79: F

Sheet Specifications
A1: tanker_nation | B1: tanker_type | C1: tanker_model | D1: receiver_nation | E1: receiver_type | F1: receiver_model | G1: c_tanker | H1: c_receiver | I1: boom_pod_BDA | J1: min_alt | K1: max_alt | L1: min_as | M1: max_as | N1: max_mach | O1: fuel_flow_rate | P1: notes
A2: Australia | B2: A330 MRTT | C2: KC-30A | D2: Australia | E2: C-17 | F2: A | G2: 3 | H2: 3 | I2: B | J2: 150 | K2: 280 | L2: 265 | M2: 285 | O2: =3600*2.20462 -> 7936.632
A3: Australia | B3: A330 MRTT | C3: KC-30A | D3: Australia | E3: E-7 | F3: A | G3: 3 | H3: 3 | I3: B | J3: 200 | K3: 300 | L3: 250 | M3: 290 | O3: =1900*2.20462 -> 4188.778
A4: Australia | B4: A330 MRTT | C4: KC-30A | D4: Australia | E4: EA-18 | F4: G | G4: 3 | H4: 3 | I4: P | J4: 15 | K4: 350 | L4: 250 | M4: 300 | O4: =1200 * 2.20462 -> 2645.544 | P4: mininimum altitude orginially given in 1500 feet
A5: Australia | B5: A330 MRTT | C5: KC-30A | D5: Australia | E5: F/A-18 | F5: A | G5: 3 | H5: 3 | I5: P | J5: 1500 ft | K5: 350 | L5: 250 | M5: 300 | O5: =1200 * 2.20462 -> 2645.544 | P5: mininimum altitude orginially given in 1500 feet
A6: Australia | B6: A330 MRTT | C6: KC-30A | D6: Australia | E6: F35 | F6: A | G6: 3 | H6: 3 | I6: B | J6: 15 | K6: 350 | L6: 265 | M6: 325 | O6: =1000*2.20462 -> 2204.62
A7: Australia | B7: A330 MRTT | C7: KC-30A | D7: Australia | E7: A330 MRTT | F7: KC-30A | G7: 3 | H7: 3 | I7: B | J7: 150 | K7: 300 | L7: 250 | M7: 290 | O7: =3600*2.20462 -> 7936.632
A8: Australia | B8: A330 MRTT | C8: KC-30A | D8: Australia | E8: P-8 | F8: A | G8: 3 | H8: 3 | I8: B | J8: 80 | K8: 280 | L8: 250 | M8: 300 | O8: =1900*2.20462 -> 4188.778
A9: Australia | B9: A330 MRTT | C9: KC-30A | D9: USA | E9: B-1 | F9: B | G9: 3 | H9: 3 | I9: B | J9: 100 | K9: 270 | L9: 290 | M9: 315 | O9: =3600*2.20462 -> 7936.632
A10: Australia | B10: A330 MRTT | C10: KC-30A | D10: USA | E10: A-10 | F10: C | G10: 3 | H10: 3 | I10: B | J10: 100 | K10: 200 | L10: 190 | M10: 240 | O10: =1200*2.20462 -> 2645.544
A11: Australia | B11: A330 MRTT | C11: KC-30A | D11: Japan | E11: F-15 | F11: J | G11: 3 | H11: itv | I11: B | J11: 100 | K11: 310 | L11: 265 | M11: 300 | O11: =1400*2.20462 -> 3086.468
A12: Australia | B12: A330 MRTT | C12: KC-30A | D12: Japan | E12: F-15 | F12: DJ | G12: 3 | H12: itv | I12: B | J12: 100 | K12: 300 | L12: 265 | M12: 300 | O12: =1400*2.20462 -> 3086.468
A13: Australia | B13: A330 MRTT | C13: KC-30A | D13: Japan | E13: F-15 | F13: K | G13: 2 | H13: itv | I13: B | J13: 100 | K13: 300 | L13: 265 | M13: 290 | O13: =1400*2.20462 -> 3086.468 | P13: For FL150-FL300 265 - 300 KCAS
A14: Australia | B14: A330 MRTT | C14: KC-30A | D14: Singapore | E14: F-15 | F14: SG | G14: 2 | H14: itv | I14: B | J14: 100 | K14: 300 | L14: 265 | M14: 290 | O14: =1400*2.20462 -> 3086.468 | P14: For FL150-FL300 265 - 300 KCAS
A15: Australia | B15: A330 MRTT | C15: KC-30A | D15: Belgium | E15: F-16 | F15: A | G15: 3 | H15: itv | I15: B | J15: 80 | K15: 300 | L15: 265 | M15: 315 | O15: =1400*2.20462 -> 3086.468 | P15: KC-30A is not cleared to refuel BAF F-16B
A16: Australia | B16: A330 MRTT | C16: KC-30A | D16: Denmark | E16: F-16 | F16: A | G16: 3 | H16: itv | I16: B | J16: 80 | K16: 300 | L16: 265 | M16: 315 | O16: =1400*2.20462 -> 3086.468 | P16: KC-30A is not cleared to refuel BAF F-16B
A17: Australia | B17: A330 MRTT | C17: KC-30A | D17: Indonesia | E17: F-16 | F17: B | G17: 3 | H17: itv | I17: B | J17: 80 | K17: 300 | L17: 265 | M17: 315 | O17: =1400*2.20462 -> 3086.468
A18: Australia | B18: A330 MRTT | C18: KC-30A | D18: Indonesia | E18: F-16 | F18: C | G18: 3 | H18: itv | I18: B | J18: 80 | K18: 300 | L18: 265 | M18: 315 | O18: =1400*2.20462 -> 3086.468
A19: Australia | B19: A330 MRTT | C19: KC-30A | D19: Indonesia | E19: F-16 | F19: D | G19: 3 | H19: itv | I19: B | J19: 80 | K19: 300 | L19: 265 | M19: 315 | O19: =1400*2.20462 -> 3086.468
A20: Australia | B20: A330 MRTT | C20: KC-30A | D20: Netherlands | E20: F-16 | F20: A | G20: 3 | H20: itv | I20: B | J20: 80 | K20: 300 | L20: 265 | M20: 315 | O20: =1400*2.20462 -> 3086.468 | P20: KC-30A is not cleared to refuel RNLAF F-16B
A21: Australia | B21: A330 MRTT | C21: KC-30A | D21: Portugal | E21: F-16 | F21: A | G21: 3 | H21: itv | I21: B | J21: 80 | K21: 300 | L21: 265 | M21: 315 | O21: =1400*2.20462 -> 3086.468 | P21: KC-30A is not cleared to refuel PoAF F-16B
A22: Australia | B22: A330 MRTT | C22: KC-30A | D22: South Korea | E22: F-16 | F22: C | G22: 3 | H22: itv | I22: B | J22: 80 | K22: 300 | L22: 265 | M22: 315 | O22: =1400*2.20462 -> 3086.468
A23: Australia | B23: A330 MRTT | C23: KC-30A | D23: Singapore | E23: F-16 | F23: C | G23: 3 | H23: itv | I23: B | J23: 80 | K23: 300 | L23: 265 | M23: 315 | O23: =1400*2.20462 -> 3086.468
A24: Australia | B24: A330 MRTT | C24: KC-30A | D24: Singapore | E24: F-16 | F24: D | G24: 3 | H24: itv | I24: B | J24: 80 | K24: 300 | L24: 265 | M24: 315 | O24: =1400*2.20462 -> 3086.468
A25: Australia | B25: A330 MRTT | C25: KC-30A | D25: Singapore | E25: F-16 | F25: D+ | G25: 3 | H25: itv | I25: B | J25: 80 | K25: 300 | L25: 265 | M25: 315 | O25: =1400*2.20462 -> 3086.468
A26: Australia | B26: A330 MRTT | C26: KC-30A | D26: Thailand | E26: F-16 | F26: A | G26: 3 | H26: itv | I26: B | J26: 80 | K26: 300 | L26: 265 | M26: 315 | O26: =1400*2.20462 -> 3086.468 | P26: KC-30A is not cleared to refuel RTAF F-16B
A27: Australia | B27: A330 MRTT | C27: KC-30A | D27: USA | E27: F-16 | F27: C | G27: 3 | H27: itv | I27: B | J27: 80 | K27: 300 | L27: 265 | M27: 315 | O27: =1400*2.20462 -> 3086.468 | P27: KC-30A is not cleared to refuel USAF F-16D
A28: Australia | B28: A330 MRTT | C28: KC-30A | D28: Japan | E28: F-2 | F28: A | G28: 3 | H28: itv | I28: B | J28: 80 | K28: 320 | L28: 265 | M28: 315 | O28: =1400*2.20462 -> 3086.468
A29: Australia | B29: A330 MRTT | C29: KC-30A | D29: Japan | E29: F-2 | F29: B | G29: 3 | H29: itv | I29: B | J29: 80 | K29: 320 | L29: 265 | M29: 315 | O29: =1400*2.20462 -> 3086.468
A30: Australia | B30: A330 MRTT | C30: KC-30A | D30: USA | E30: F-22 | F30: A | G30: 3 | H30: itv | I30: B | J30: 80 | K30: 350 | L30: 270 | M30: 315 | O30: =800*2.20462 -> 1763.696
A31: Australia | B31: A330 MRTT | C31: KC-30A | D31: Italy | E31: F-35 | F31: A | G31: 3 | H31: itv | I31: B | J31: 80 | K31: 350 | L31: 265 | M31: 325 | O31: =1000*2.20462 -> 2204.62
A32: Australia | B32: A330 MRTT | C32: KC-30A | D32: Japan | E32: F-35 | F32: A | G32: 3 | H32: itv | I32: B | J32: 80 | K32: 350 | L32: 265 | M32: 325 | O32: =1000*2.20462 -> 2204.62
A33: Australia | B33: A330 MRTT | C33: KC-30A | D33: Denmark | E33: F-35 | F33: A | G33: 3 | H33: itv | I33: B | J33: 80 | K33: 350 | L33: 265 | M33: 325 | O33: =1000*2.20462 -> 2204.62
A34: Australia | B34: A330 MRTT | C34: KC-30A | D34: Netherlands | E34: F-35 | F34: A | G34: 3 | H34: itv | I34: B | J34: 80 | K34: 350 | L34: 265 | M34: 325 | O34: =1000*2.20462 -> 2204.62
A35: Australia | B35: A330 MRTT | C35: KC-30A | D35: Norway | E35: F-35 | F35: A | G35: 3 | H35: itv | I35: B | J35: 80 | K35: 350 | L35: 265 | M35: 325 | O35: =1000*2.20462 -> 2204.62
A36: Australia | B36: A330 MRTT | C36: KC-30A | D36: South Korea | E36: F-35 | F36: A | G36: 3 | H36: itv | I36: B | J36: 80 | K36: 350 | L36: 265 | M36: 325 | O36: =1000*2.20462 -> 2204.62
A37: Australia | B37: A330 MRTT | C37: KC-30A | D37: USA | E37: F-35 | F37: A | G37: 3 | H37: itv | I37: B | J37: 80 | K37: 350 | L37: 265 | M37: 325 | O37: =1000*2.20462 -> 2204.62
A38: Australia | B38: A330 MRTT | C38: KC-30A | D38: Singapore | E38: A330 MRTT | F38: A-330 MRTT | G38: 3 | H38: itv | I38: B | J38: 150 | K38: 300 | L38: 250 | M38: 290 | O38: =3600*2.20462 -> 7936.632
A39: Australia | B39: A330 MRTT | C39: KC-30A | D39: USN | E39: P-8 | F39: A | G39: 3 | H39: itv | I39: B | J39: 80 | K39: 280 | L39: 250 | M39: 300 | O39: =1900*2.20462 -> 4188.778
A40: Australia | B40: A330 MRTT | C40: KC-30A | D40: USA | E40: B-2 | F40: A | G40: 3 | H40: itv | I40: B | J40: 100 | K40: 270 | L40: 250 | M40: 270 | O40: =3600*2.20462 -> 7936.632
...

Sheet Australia
A1: {=Specifications!A1:P1} -> tanker_nation | B1: tanker_type | C1: tanker_model | D1: receiver_nation | E1: receiver_type | F1: receiver_model | G1: c_tanker | H1: c_receiver | I1: boom_pod_BDA | J1: min_alt | K1: max_alt | L1: min_as | M1: max_as | N1: max_mach | O1: fuel_flow_rate | P1: notes
A2: {=_xlfn.SORTBY( _xlfn._xlws.FILTER(Specifications!B:P, Specifications!A:A="Australia", ""), _xlfn._xlws.FILTER(Specifications!B:B, Specifications!A:A="Australia"), 1, _xlfn._xlws.FILTER(Specifications!D:D, Specifications!A:A="Australia"), 1 )} -> A330 MRTT | B2: KC-30A | C2: Australia | D2: C-17 | E2: A | F2: 3 | G2: 3 | H2: B | I2: 150 | J2: 280 | K2: 265 | L2: 285 | M2: 0 | N2: 7936.632 | O2: 0
A3: A330 MRTT | B3: KC-30A | C3: Australia | D3: E-7 | E3: A | F3: 3 | G3: 3 | H3: B | I3: 200 | J3: 300 | K3: 250 | L3: 290 | M3: 0 | N3: 4188.778 | O3: 0
A4: A330 MRTT | B4: KC-30A | C4: Australia | D4: EA-18 | E4: G | F4: 3 | G4: 3 | H4: P | I4: 15 | J4: 350 | K4: 250 | L4: 300 | M4: 0 | N4: 2645.544 | O4: mininimum altitude orginially given in 1500 feet
A5: A330 MRTT | B5: KC-30A | C5: Australia | D5: F/A-18 | E5: A | F5: 3 | G5: 3 | H5: P | I5: 1500 ft | J5: 350 | K5: 250 | L5: 300 | M5: 0 | N5: 2645.544 | O5: mininimum altitude orginially given in 1500 feet
A6: A330 MRTT | B6: KC-30A | C6: Australia | D6: F35 | E6: A | F6: 3 | G6: 3 | H6: B | I6: 15 | J6: 350 | K6: 265 | L6: 325 | M6: 0 | N6: 2204.62 | O6: 0
A7: A330 MRTT | B7: KC-30A | C7: Australia | D7: A330 MRTT | E7: KC-30A | F7: 3 | G7: 3 | H7: B | I7: 150 | J7: 300 | K7: 250 | L7: 290 | M7: 0 | N7: 7936.632 | O7: 0
A8: A330 MRTT | B8: KC-30A | C8: Australia | D8: P-8 | E8: A | F8: 3 | G8: 3 | H8: B | I8: 80 | J8: 280 | K8: 250 | L8: 300 | M8: 0 | N8: 4188.778 | O8: 0
A9: A330 MRTT | B9: KC-30A | C9: Belgium | D9: F-16 | E9: A | F9: 3 | G9: itv | H9: B | I9: 80 | J9: 300 | K9: 265 | L9: 315 | M9: 0 | N9: 3086.468 | O9: KC-30A is not cleared to refuel BAF F-16B
A10: A330 MRTT | B10: KC-30A | C10: Canada | D10: CF/A-18 | E10: A | F10: 3 | G10: itv | H10: P | I10: 150 | J10: 350 | K10: 250 | L10: 300 | M10: 0 | N10: 2425.082 | O10: 0
A11: A330 MRTT | B11: KC-30A | C11: Canada | D11: CF/A-18 | E11: B | F11: 3 | G11: itv | H11: P | I11: 150 | J11: 350 | K11: 250 | L11: 300 | M11: 0 | N11: 2425.082 | O11: 0
A12: A330 MRTT | B12: KC-30A | C12: Denmark | D12: F-16 | E12: A | F12: 3 | G12: itv | H12: B | I12: 80 | J12: 300 | K12: 265 | L12: 315 | M12: 0 | N12: 3086.468 | O12: KC-30A is not cleared to refuel BAF F-16B
A13: A330 MRTT | B13: KC-30A | C13: Denmark | D13: F-35 | E13: A | F13: 3 | G13: itv | H13: B | I13: 80 | J13: 350 | K13: 265 | L13: 325 | M13: 0 | N13: 2204.62 | O13: 0
A14: A330 MRTT | B14: KC-30A | C14: Finland | D14: F/A-18 | E14: C | F14: 3 | G14: itv | H14: P | I14: 150 | J14: 350 | K14: 250 | L14: 300 | M14: 0 | N14: 2425.082 | O14: 0
A15: A330 MRTT | B15: KC-30A | C15: Finland | D15: F/A-18 | E15: D | F15: 3 | G15: itv | H15: P | I15: 150 | J15: 350 | K15: 250 | L15: 300 | M15: 0 | N15: 2425.082 | O15: 0
A16: A330 MRTT | B16: KC-30A | C16: France | D16: Rafale | E16: B | F16: 3 | G16: itv | H16: P | I16: 100 | J16: 350 | K16: 180 | L16: 325 | M16: 0 | N16: 2425.082 | O16: 0
A17: A330 MRTT | B17: KC-30A | C17: France | D17: Rafale | E17: C | F17: 3 | G17: itv | H17: P | I17: 100 | J17: 350 | K17: 180 | L17: 325 | M17: 0 | N17: 2425.082 | O17: 0
A18: A330 MRTT | B18: KC-30A | C18: France | D18: Rafale | E18: M | F18: 3 | G18: itv | H18: P | I18: 100 | J18: 350 | K18: 180 | L18: 325 | M18: 0 | N18: 2425.082 | O18: 0
A19: A330 MRTT | B19: KC-30A | C19: Germany | D19: EF-2000 | E19: EF-2000 | F19: 3 | G19: itv | H19: P | I19: 20 | J19: 350 | K19: 260 | L19: 325 | M19: 0 | N19: 2425.082 | O19: 0
A20: A330 MRTT | B20: KC-30A | C20: Indian | D20: Rafale | E20: EH | F20: 3 | G20: itv | H20: P | I20: 100 | J20: 350 | K20: 180 | L20: 325 | M20: 0 | N20: 2425.082 | O20: 0
A21: A330 MRTT | B21: KC-30A | C21: Indian | D21: Rafale | E21: DH | F21: 3 | G21: itv | H21: P | I21: 100 | J21: 350 | K21: 180 | L21: 325 | M21: 0 | N21: 2425.082 | O21: 0
A22: A330 MRTT | B22: KC-30A | C22: Indian | D22: SU-30 | E22: MKI | F22: 2 | G22: itv | H22: P | I22: 100 | J22: 320 | K22: 250 | L22: 300 | M22: 0 | N22: 1984.158 | O22: 0
A23: A330 MRTT | B23: KC-30A | C23: Indonesia | D23: F-16 | E23: B | F23: 3 | G23: itv | H23: B | I23: 80 | J23: 300 | K23: 265 | L23: 315 | M23: 0 | N23: 3086.468 | O23: 0
A24: A330 MRTT | B24: KC-30A | C24: Indonesia | D24: F-16 | E24: C | F24: 3 | G24: itv | H24: B | I24: 80 | J24: 300 | K24: 265 | L24: 315 | M24: 0 | N24: 3086.468 | O24: 0
... A30: A330 MRTT | B30: KC-30A | C30: Japan | D30: F-15 | E30: DJ | F30: 3 | G30: itv | H30: B | I30: 100 | J30: 300 | K30: 265 | L30: 300 | M30: 0 | N30: 3086.468 | O30: 0
A31: A330 MRTT | B31: KC-30A | C31: Japan | D31: F-15 | E31: K | F31: 2 | G31: itv | H31: B | I31: 100 | J31: 300 | K31: 265 | L31: 290 | M31: 0 | N31: 3086.468 | O31: For FL150-FL300 265 - 300 KCAS
A32: A330 MRTT | B32: KC-30A | C32: Japan | D32: F-2 | E32: A | F32: 3 | G32: itv | H32: B | I32: 80 | J32: 320 | K32: 265 | L32: 315 | M32: 0 | N32: 3086.468 | O32: 0
A33: A330 MRTT | B33: KC-30A | C33: Japan | D33: F-2 | E33: B | F33: 3 | G33: itv | H33: B | I33: 80 | J33: 320 | K33: 265 | L33: 315 | M33: 0 | N33: 3086.468 | O33: 0
A34: A330 MRTT | B34: KC-30A | C34: Japan | D34: F-35 | E34: A | F34: 3 | G34: itv | H34: B | I34: 80 | J34: 350 | K34: 265 | L34: 325 | M34: 0 | N34: 2204.62 | O34: 0
A35: A330 MRTT | B35: KC-30A | C35: Japan | D35: F-35 | E35: B | F35: 3 | G35: itv | H35: P | I35: 150 | J35: 350 | K35: 260 | L35: 300 | M35: 0 | N35: 1984.158 | O35: 0
A36: A330 MRTT | B36: KC-30A | C36: Malaysia | D36: F/A-18 | E36: D | F36: 3 | G36: itv | H36: P | I36: 150 | J36: 350 | K36: 250 | L36: 300 | M36: 0 | N36: 2425.082 | O36: 0
A37: A330 MRTT | B37: KC-30A | C37: Malaysia | D37: SU-30 | E37: MKM | F37: 2 | G37: itv | H37: P | I37: 100 | J37: 320 | K37: 250 | L37: 300 | M37: 0 | N37: 1984.158 | O37: 0
A38: A330 MRTT | B38: KC-30A | C38: NATO | D38: C-17 | E38: A | F38: 3 | G38: itv | H38: B | I38: 150 | J38: 280 | K38: 265 | L38: 285 | M38: 0 | N38: 7936.632 | O38: 0
A39: A330 MRTT | B39: KC-30A | C39: Netherlands | D39: F-16 | E39: A | F39: 3 | G39: itv | H39: B | I39: 80 | J39: 300 | K39: 265 | L39: 315 | M39: 0 | N39: 3086.468 | O39: KC-30A is not cleared to refuel RNLAF F-16B
A40: A330 MRTT | B40: KC-30A | C40: Netherlands | D40: F-35 | E40: A | F40: 3 | G40: itv | H40: B | I40: 80 | J40: 350 | K40: 265 | L40: 325 | M40: 0 | N40: 2204.62 | O40: 0
A41: A330 MRTT | B41: KC-30A | C41: Norway | D41: F-35 | E41: A | F41: 3 | G41: itv | H41: B | I41: 80 | J41: 350 | K41: 265 | L41: 325 | M41: 0 | N41: 2204.62 | O41: 0
A42: A330 MRTT | B42: KC-30A | C42: Portugal | D42: F-16 | E42: A | F42: 3 | G42: itv | H42: B | I42: 80 | J42: 300 | K42: 265 | L42: 315 | M42: 0 | N42: 3086.468 | O42: KC-30A is not cleared to refuel PoAF F-16B
A43: A330 MRTT | B43: KC-30A | C43: Singapore | D43: F-15 | E43: SG | F43: 2 | G43: itv | H43: B | I43: 100 | J43: 300 | K43: 265 | L43: 290 | M43: 0 | N43: 3086.468 | O43: For FL150-FL300 265 - 300 KCAS
A44: A330 MRTT | B44: KC-30A | C44: Singapore | D44: F-16 | E44: C | F44: 3 | G44: itv | H44: B | I44: 80 | J44: 300 | K44: 265 | L44: 315 | M44: 0 | N44: 3086.468 | O44: 0
A45: A330 MRTT | B45: KC-30A | C45: Singapore | D45: F-16 | E45: D | F45: 3 | G45: itv | H45: B | I45: 80 | J45: 300 | K45: 265 | L45: 315 | M45: 0 | N45: 3086.468 | O45: 0
...

Sheet Canada
A2: {=_xlfn.SORTBY( _xlfn._xlws.FILTER(Specifications!B:P, Specifications!A:A="Canada", ""), _xlfn._xlws.FILTER(Specifications!B:B, Specifications!A:A="Canada"), 1, _xlfn._xlws.FILTER(Specifications!D:D, Specifications!A:A="Canada"), 1 )} -> CC-150 | B2: T | C2: Australia | D2: F/A-18 | E2: F | F2: itv | G2: 3 | H2: P | I2: 100 | J2: 250 | K2: 230 | L2: 270 | M2: 0 | N2: 0 | O2: 0
A3: CC-150 | B3: T | C3: Australia | D3: EA-18 | E3: G | F3: itv | G3: 3 | H3: P | I3: 100 | J3: 250 | K3: 230 | L3: 270 | M3: 0 | N3: 0 | O3: 0
R4: tanker_type | S4: tanker_model | T4: receiver_nation | U4: receiver_type | V4: receiver_model | W4: c_tanker | X4: c_receiver | Y4: boom_pod_BDA | Z4: min_alt | AA4: max_alt | AB4: min_as | AC4: max_as | AD4: max_Mach | AE4: fuel_flow_rate | AF4: notes

Sheet France
A2: {=_xlfn.SORTBY( _xlfn._xlws.FILTER(Specifications!B:P, Specifications!A:A="France", ""), _xlfn._xlws.FILTER(Specifications!B:B, Specifications!A:A="France"), 1, _xlfn._xlws.FILTER(Specifications!D:D, Specifications!A:A="France"), 1 )} -> A330 MRTT | B2: Phénix | C2: Australia | D2: C-17 | E2: A | F2: itv | G2: 3 | H2: B | I2: 150 | J2: 280 | K2: 265 | L2: 285 | M2: 0 | N2: 0 | O2: 0
A3: A330 MRTT | B3: Phénix | C3: Australia | D3: E-7 | E3: A | F3: itv | G3: 3 | H3: B | I3: 200 | J3: 300 | K3: 250 | L3: 290 | M3: 0 | N3: 0 | O3: 0
A4: A330 MRTT | B4: Phénix | C4: Australia | D4: EA-18 | E4: G | F4: itv | G4: 3 | H4: P | I4: 15 | J4: 350 | K4: 250 | L4: 300 | M4: 0 | N4: 0 | O4: given in 1500 ft
A5: A330 MRTT | B5: Phénix | C5: Australia | D5: F/A-18 | E5: F | F5: itv | G5: 3 | H5: P | I5: 15 | J5: 350 | K5: 250 | L5: 300 | M5: 0 | N5: 0 | O5: given in 1500 ft
A6: A330 MRTT | B6: Phénix | C6: Australia | D6: F-35 | E6: A | F6: itv | G6: 3 | H6: B | I6: 80 | J6: 350 | K6: 265 | L6: 325 | M6: 0 | N6: 0 | O6: 0
A7: A330 MRTT | B7: Phénix | C7: Australia | D7: A330 MRTT | E7: KC-30A | F7: itv | G7: 3 | H7: B | I7: 150 | J7: 300 | K7: 250 | L7: 290 | M7: 0 | N7: 0 | O7: 0
A8: A330 MRTT | B8: Phénix | C8: Australia | D8: P-8 | E8: A | F8: itv | G8: 3 | H8: B | I8: 80 | J8: 280 | K8: 250 | L8: 300 | M8: 0 | N8: 0 | O8: 0
A9: C-135 | B9: FR | C9: Australia | D9: E-7 | E9: A | F9: itv | G9: 3 | H9: B | I9: 200 | J9: 300 | K9: 250 | L9: 290 | M9: 0 | N9: 0 | O9: 0
A10: C-135 | B10: FR | C10: Australia | D10: F/A-18 | E10: F | F10: itv | G10: 3 | H10: BDA | I10: 100 | J10: 285 | K10: 200 | L10: 275 | M10: 0 | N10: 0 | O10: 0
A11: C-135 | B11: FR | C11: Australia | D11: F/A-18 | E11: F | F11: itv | G11: 3 | H11: P | I11: 100 | J11: 285 | K11: 200 | L11: 275 | M11: 0 | N11: 0 | O11: 0
A12: C-135 | B12: FR | C12: Australia | D12: EA-18 | E12: G | F12: itv | G12: 3 | H12: BDA | I12: 100 | J12: 285 | K12: 200 | L12: 275 | M12: 0 | N12: 0 | O12: 0
A13: C-135 | B13: FR | C13: Australia | D13: EA-18 | E13: G | F13: itv | G13: 3 | H13: P | I13: 100 | J13: 285 | K13: 200 | L13: 275 | M13: 0 | N13: 0 | O13: 0
A14: C-135 | B14: FR | C14: Australia | D14: P-8 | E14: A | F14: itv | G14: 3 | H14: B | I14: 80 | J14: 280 | K14: 250 | L14: 300 | M14: 0 | N14: 0 | O14: 0
A15: KC-135 | B15: RG | C15: Australia | D15: E-7 | E15: A | F15: itv | G15: 3 | H15: B | I15: 200 | J15: 300 | K15: 250 | L15: 290 | M15: 0 | N15: 0 | O15: 0
A16: KC-135 | B16: RG | C16: Australia | D16: F/A-18 | E16: F | F16: itv | G16: 3 | H16: B | I16: 100 | J16: 285 | K16: 200 | L16: 275 | M16: 0 | N16: 0 | O16: 0
A17: KC-135 | B17: RG | C17: Australia | D17: EA-18 | E17: G | F17: itv | G17: 3 | H17: BDA | I17: 100 | J17: 285 | K17: 200 | L17: 275 | M17: 0 | N17: 0 | O17: 0
... A19: KC-135 | B19: RG | C19: Australia | D19: P-8 | E19: A | F19: itv | G19: 3 | H19: B | I19: 80 | J19: 280 | K19: 250 | L19: 300 | M19: 0 | N19: 0 | O19: 0

Sheet Germany
A2: {=_xlfn.SORTBY( _xlfn._xlws.FILTER(Specifications!B:P, Specifications!A:A="Germany", ""), _xlfn._xlws.FILTER(Specifications!B:B, Specifications!A:A="Germany"), 1, _xlfn._xlws.FILTER(Specifications!D:D, Specifications!A:A="Germany"), 1 )} -> #VALUE!

Sheet Italy
A2: {=_xlfn.SORTBY( _xlfn._xlws.FILTER(Specifications!B:P, Specifications!A:A="Italy", ""), _xlfn._xlws.FILTER(Specifications!B:B, Specifications!A:A="Italy"), 1, _xlfn._xlws.FILTER(Specifications!D:D, Specifications!A:A="Italy"), 1 )} -> KC-130 | B2: J | C2: Australia | D2: F/A-18 | E2: F | F2: itv | G2: 3 | H2: P | I2: 50 | J2: 250 | K2: 185 | L2: 250 | M2: 0 | N2: 0 | O2: 0
A3: KC-130 | B3: J | C3: Australia | D3: EA-18 | E3: G | F3: itv | G3: 3 | H3: P | I3: 50 | J3: 250 | K3: 185 | L3: 250 | M3: 0 | N3: 0 | O3: 0
A4: KC-767 | B4: A | C4: Australia | D4: F/A-18 | E4: F | F4: itv | G4: 3 | H4: BDA | I4: 150 | J4: 350 | K4: 225 | L4: 300 | M4: 0 | N4: 4005 | O4: 0
A5: KC-767 | B5: A | C5: Australia | D5: EA-18 | E5: G | F5: itv | G5: 3 | H5: BDA | I5: 150 | J5: 350 | K5: 225 | L5: 300 | M5: 0 | N5: 4005 | O5: 0
A6: KC-767 | B6: A | C6: Australia | D6: F/A-18 | E6: F | F6: itv | G6: 3 | H6: P | I6: 150 | J6: 350 | K6: 225 | L6: 300 | M6: 0 | N6: 2670 | O6: 0
A7: KC-767 | B7: A | C7: Australia | D7: EA-18 | E7: G | F7: itv | G7: 3 | H7: P | I7: 150 | J7: 350 | K7: 225 | L7: 300 | M7: 0 | N7: 2670 | O7: 0
A8: KC-767 | B8: A | C8: Australia | D8: F-35 | E8: A | F8: itv | G8: 3 | H8: B | I8: 100 | J8: 300 | K8: 265 | L8: 325 | M8: 0 | N8: 0 | O8: 0

Sheet Japan
A2: {=_xlfn.SORTBY( _xlfn._xlws.FILTER(Specifications!B:P, Specifications!A:A="Japan", ""), _xlfn._xlws.FILTER(Specifications!B:B, Specifications!A:A="Japan"), 1, _xlfn._xlws.FILTER(Specifications!D:D, Specifications!A:A="Japan"), 1 )} -> KC-46 | B2: A | C2: Australia | D2: F-35 | E2: A | F2: itv | G2: 2 | H2: B | I2: 100 | J2: 350 | K2: 265 | L2: 325 | M2: 0 | N2: 0 | O2: 0
A3: KC-767 | B3: J | C3: Australia | D3: F-35 | E3: A | F3: itv | G3: 3 | H3: B | I3: 100 | J3: 300 | K3: 265 | L3: 325 | M3: 0 | N3: 0 | O3: 0

Sheet Malaysia
A2: {=_xlfn.SORTBY( _xlfn._xlws.FILTER(Specifications!B:P, Specifications!A:A="Malaysia", ""), _xlfn._xlws.FILTER(Specifications!B:B, Specifications!A:A="Malaysia"), 1, _xlfn._xlws.FILTER(Specifications!D:D, Specifications!A:A="Malaysia"), 1 )} -> A400 | B2: M | C2: Australia | D2: F/A-18 | E2: F | F2: itv | G2: 1 | H2: P | I2: 150 | J2: 250 | K2: 230 | L2: 270 | M2: 0 | N2: 0 | O2: WDE (Wing Dispensing Equipment) Only
A3: A400 | B3: M | C3: Australia | D3: EA-18 | E3: G | F3: itv | G3: 1 | H3: P | I3: 150 | J3: 250 | K3: 230 | L3: 270 | M3: 0 | N3: 0 | O3: WDE (Wing Dispensing Equipment) Only

Sheet MMF
A2: {=_xlfn.SORTBY( _xlfn._xlws.FILTER(Specifications!B:P, Specifications!A:A="MMF", ""), _xlfn._xlws.FILTER(Specifications!B:B, Specifications!A:A="MMF"), 1, _xlfn._xlws.FILTER(Specifications!D:D, Specifications!A:A="MMF"), 1 )} -> A330 MRTT | B2: KC-30M | C2: Australia | D2: C-17 | E2: A | F2: itv | G2: 3 | H2: B | I2: 150 | J2: 280 | K2: 265 | L2: 285 | M2: 0 | N2: 0 | O2: 0
A3: A330 MRTT | B3: KC-30M | C3: Australia | D3: E-7 | E3: A | F3: itv | G3: 3 | H3: B | I3: 200 | J3: 300 | K3: 250 | L3: 290 | M3: 0 | N3: 0 | O3: 0
A4: A330 MRTT | B4: KC-30M | C4: Australia | D4: EA-18 | E4: G | F4: itv | G4: 3 | H4: P | I4: 15 | J4: 350 | K4: 250 | L4: 300 | M4: 0 | N4: 0 | O4: given in 1500 ft
A5: A330 MRTT | B5: KC-30M | C5: Australia | D5: F/A-18 | E5: F | F5: itv | G5: 3 | H5: P | I5: 15 | J5: 350 | K5: 250 | L5: 300 | M5: 0 | N5: 0 | O5: given in 1500 ft
A6: A330 MRTT | B6: KC-30M | C6: Australia | D6: F-35 | E6: A | F6: itv | G6: 3 | H6: B | I6: 80 | J6: 350 | K6: 265 | L6: 325 | M6: 0 | N6: 0 | O6: 0
A7: A330 MRTT | B7: KC-30M | C7: Australia | D7: A330 MRTT | E7: KC-30A | F7: itv | G7: 3 | H7: B | I7: 150 | J7: 300 | K7: 250 | L7: 290 | M7: 0 | N7: 0 | O7: 0
A8: A330 MRTT | B8: KC-30M | C8: Australia | D8: P-8 | E8: A | F8: itv | G8: 3 | H8: B | I8: 80 | J8: 280 | K8: 250 | L8: 300 | M8: 0 | N8: 0 | O8: 0

Sheet MSM
A2: {=_xlfn.SORTBY( _xlfn._xlws.FILTER(Specifications!B:P, Specifications!A:A="MSM", ""), _xlfn._xlws.FILTER(Specifications!B:B, Specifications!A:A="MSM"), 1, _xlfn._xlws.FILTER(Specifications!D:D, Specifications!A:A="MSM"), 1 )} -> KC-135 | B2: R | C2: Australia | D2: C-17 | E2: A | F2: itv | G2: 3 | H2: B | I2: 120 | J2: 310 | K2: 260 | L2: 270 | M2: 0 | N2: 0 | O2: 0
A3: KC-135 | B3: R | C3: Australia | D3: E-7 | E3: A | F3: itv | G3: 3 | H3: B | I3: 200 | J3: 300 | K3: 250 | L3: 290 | M3: 0 | N3: 0 | O3: 0
A4: KC-135 | B4: R | C4: Australia | D4: F/A-18 | E4: F | F4: itv | G4: 3 | H4: BDA | I4: 50 | J4: 350 | K4: 200 | L4: 275 | M4: 0 | N4: 0 | O4: 0
A5: KC-135 | B5: R | C5: Australia | D5: F/A-18 | E5: F | F5: itv | G5: 3 | H5: P | I5: 50 | J5: 350 | K5: 220 | L5: 270 | M5: 0 | N5: 0 | O5: 0
A6: KC-135 | B6: R | C6: Australia | D6: EA-18 | E6: G | F6: itv | G6: 3 | H6: BDA | I6: 50 | J6: 350 | K6: 200 | L6: 275 | M6: 0 | N6: 0 | O6: 0
A7: KC-135 | B7: R | C7: Australia | D7: EA-18 | E7: G | F7: itv | G7: 3 | H7: P | I7: 50 | J7: 350 | K7: 220 | L7: 270 | M7: 0 | N7: 0 | O7: 0
A8: KC-135 | B8: R | C8: Australia | D8: F-35 | E8: A | F8: itv | G8: 3 | H8: B | I8: 100 | J8: 300 | K8: 230 | L8: 350 | M8: 0 | N8: 0 | O8: 0
A9: KC-135 | B9: R | C9: Australia | D9: P-8 | E9: A | F9: itv | G9: 3 | H9: B | I9: 80 | J9: 280 | K9: 250 | L9: 300 | M9: 0 | N9: 0 | O9: 0

Sheet NATO
A2: {=_xlfn.SORTBY( _xlfn._xlws.FILTER(Specifications!B:P, Specifications!A:A="NATO", ""), _xlfn._xlws.FILTER(Specifications!B:B, Specifications!A:A="NATO"), 1, _xlfn._xlws.FILTER(Specifications!D:D, Specifications!A:A="NATO"), 1 )} -> #VALUE!

Sheet Omega
A2: {=_xlfn.SORTBY( _xlfn._xlws.FILTER(Specifications!B:P, Specifications!A:A="Omega", ""), _xlfn._xlws.FILTER(Specifications!B:B, Specifications!A:A="Omega"), 1, _xlfn._xlws.FILTER(Specifications!D:D, Specifications!A:A="Omega"), 1 )} -> KC-10 | B2: KDC-10B | C2: Australia | D2: C-17 | E2: A | F2: itv | G2: 3 | H2: B | I2: 120 | J2: 310 | K2: 275 | L2: 290 | M2: 0 | N2: 0 | O2: 0
A3: KC-10 | B3: KDC-10A | C3: Australia | D3: F/A-18 | E3: F | F3: itv | G3: 3 | H3: P | I3: 50 | J3: 330 | K3: 200 | L3: 300 | M3: 0 | N3: 0 | O3: 0
A4: KC-10 | B4: KDC-10A | C4: Australia | D4: EA-18 | E4: G | F4: itv | G4: 3 | H4: P | I4: 50 | J4: 330 | K4: 200 | L4: 300 | M4: 0 | N4: 0 | O4: 0
A5: KDC-10 | B5: B | C5: Australia | D5: E-7 | E5: A | F5: itv | G5: 0 | H5: B | I5: 200 | J5: 320 | K5: 250 | L5: 290 | M5: 0 | N5: 0 | O5: 0
A6: KDC-10 | B6: B | C6: Australia | D6: F-35 | E6: A | F6: itv | G6: 3 | H6: B | I6: 100 | J6: 300 | K6: 230 | L6: 350 | M6: 0 | N6: 0 | O6: 0

Sheet Singapore
A2: {=_xlfn.SORTBY( _xlfn._xlws.FILTER(Specifications!B:P, Specifications!A:A="Singapore", ""), _xlfn._xlws.FILTER(Specifications!B:B, Specifications!A:A="Singapore"), 1, _xlfn._xlws.FILTER(Specifications!D:D, Specifications!A:A="Singapore"), 1 )} -> A330 MRTT | B2: A330 MRTT | C2: Australia | D2: C-17 | E2: A | F2: itv | G2: 3 | H2: B | I2: 150 | J2: 280 | K2: 265 | L2: 285 | M2: 0 | N2: 0 | O2: 0
A3: A330 MRTT | B3: A330 MRTT | C3: Australia | D3: E-7 | E3: A | F3: itv | G3: 3 | H3: B | I3: 200 | J3: 300 | K3: 250 | L3: 290 | M3: 0 | N3: 0 | O3: 0
A4: A330 MRTT | B4: A330 MRTT | C4: Australia | D4: EA-18 | E4: G | F4: itv | G4: 3 | H4: P | I4: 15 | J4: 350 | K4: 250 | L4: 300 | M4: 0 | N4: 0 | O4: given in 1500 ft
A5: A330 MRTT | B5: A330 MRTT | C5: Australia | D5: F/A-18 | E5: F | F5: itv | G5: 3 | H5: P | I5: 15 | J5: 350 | K5: 250 | L5: 300 | M5: 0 | N5: 0 | O5: given in 1500 ft
A6: A330 MRTT | B6: A330 MRTT | C6: Australia | D6: F-35 | E6: A | F6: itv | G6: 3 | H6: B | I6: 80 | J6: 350 | K6: 265 | L6: 325 | M6: 0 | N6: 0 | O6: 0
A7: A330 MRTT | B7: A330 MRTT | C7: Australia | D7: A330 MRTT | E7: KC-30A | F7: itv | G7: 3 | H7: B | I7: 150 | J7: 300 | K7: 250 | L7: 290 | M7: 0 | N7: 0 | O7: 0
A8: A330 MRTT | B8: A330 MRTT | C8: Australia | D8: P-8 | E8: A | F8: itv | G8: 3 | H8: B | I8: 80 | J8: 280 | K8: 250 | L8: 300 | M8: 0 | N8: 0 | O8: 0

Sheet South Korea
A2: {=_xlfn.SORTBY( _xlfn._xlws.FILTER(Specifications!B:P, Specifications!A:A="South Korea", ""), _xlfn._xlws.FILTER(Specifications!B:B, Specifications!A:A="South Korea"), 1, _xlfn._xlws.FILTER(Specifications!D:D, Specifications!A:A="South Korea"), 1 )} -> A330 MRTT | B2: KC-330 | C2: Australia | D2: C-17 | E2: A | F2: itv | G2: 3 | H2: B | I2: 150 | J2: 280 | K2: 265 | L2: 285 | M2: 0 | N2: 0 | O2: 0
A3: A330 MRTT | B3: KC-330 | C3: Australia | D3: E-7 | E3: A | F3: itv | G3: 3 | H3: B | I3: 200 | J3: 300 | K3: 250 | L3: 290 | M3: 0 | N3: 0 | O3: 0
A4: A330 MRTT | B4: KC-330 | C4: Australia | D4: EA-18 | E4: G | F4: itv | G4: 3 | H4: P | I4: 15 | J4: 350 | K4: 250 | L4: 300 | M4: 0 | N4: 0 | O4: given in 1500 ft
A5: A330 MRTT | B5: KC-330 | C5: Australia | D5: F/A-18 | E5: F | F5: itv | G5: 3 | H5: P | I5: 15 | J5: 350 | K5: 250 | L5: 300 | M5: 0 | N5: 0 | O5: given in 1500 ft
A6: A330 MRTT | B6: KC-330 | C6: Australia | D6: F-35 | E6: A | F6: itv | G6: 3 | H6: B | I6: 80 | J6: 350 | K6: 265 | L6: 325 | M6: 0 | N6: 0 | O6: 0
A7: A330 MRTT | B7: KC-330 | C7: Australia | D7: A330 MRTT | E7: KC-30A | F7: itv | G7: 3 | H7: B | I7: 150 | J7: 300 | K7: 250 | L7: 290 | M7: 0 | N7: 0 | O7: 0
A8: A330 MRTT | B8: KC-330 | C8: Australia | D8: P-8 | E8: A | F8: itv | G8: 3 | H8: B | I8: 80 | J8: 280 | K8: 250 | L8: 300 | M8: 0 | N8: 0 | O8: 0

Sheet Spain
A2: {=_xlfn.SORTBY( _xlfn._xlws.FILTER(Specifications!B:P, Specifications!A:A="Spain", ""), _xlfn._xlws.FILTER(Specifications!B:B, Specifications!A:A="Spain"), 1, _xlfn._xlws.FILTER(Specifications!D:D, Specifications!A:A="Spain"), 1 )} -> #VALUE!

Sheet Sweden
A2: {=_xlfn.SORTBY( _xlfn._xlws.FILTER(Specifications!B:P, Specifications!A:A="Sweden", ""), _xlfn._xlws.FILTER(Specifications!B:B, Specifications!A:A="Sweden"), 1, _xlfn._xlws.FILTER(Specifications!D:D, Specifications!A:A="Sweden"), 1 )} -> #VALUE!

Sheet Turkey
A2: {=_xlfn.SORTBY( _xlfn._xlws.FILTER(Specifications!B:P, Specifications!A:A="Turkey", ""), _xlfn._xlws.FILTER(Specifications!B:B, Specifications!A:A="Turkey"), 1, _xlfn._xlws.FILTER(Specifications!D:D, Specifications!A:A="Turkey"), 1 )} -> #VALUE!

Sheet UK
A2: {=_xlfn.SORTBY( _xlfn._xlws.FILTER(Specifications!B:P, Specifications!A:A="UK", ""), _xlfn._xlws.FILTER(Specifications!B:B, Specifications!A:A="UK"), 1, _xlfn._xlws.FILTER(Specifications!D:D, Specifications!A:A="UK"), 1 )} -> #VALUE!

Sheet USA
A2: {=_xlfn.SORTBY( _xlfn._xlws.FILTER(Specifications!B:P, Specifications!A:A="USA", ""), _xlfn._xlws.FILTER(Specifications!B:B, Specifications!A:A="USA"), 1, _xlfn._xlws.FILTER(Specifications!D:D, Specifications!A:A="USA"), 1 )} -> KC-10 | B2: A | C2: Australia | D2: C-17 | E2: A | F2: itv | G2: 3 | H2: B | I2: 120 | J2: 310 | K2: 275 | L2: 290 | M2: 0 | N2: 0 | O2: 0
A3: KC-10 | B3: A | C3: Australia | D3: E-7 | E3: A | F3: itv | G3: 3 | H3: B | I3: 200 | J3: 320 | K3: 250 | L3: 290 | M3: 0 | N3: 0 | O3: 0
A4: KC-10 | B4: A | C4: Australia | D4: F/A-18 | E4: F | F4: itv | G4: 3 | H4: P | I4: 100 | J4: 320 | K4: 230 | L4: 305 | M4: 0 | N4: 0 | O4: 0
A5: KC-10 | B5: A | C5: Australia | D5: EA-18 | E5: G | F5: itv | G5: 3 | H5: P | I5: 100 | J5: 320 | K5: 230 | L5: 305 | M5: 0 | N5: 0 | O5: 0
A6: KC-10 | B6: A | C6: Australia | D6: F/A-18 | E6: F | F6: itv | G6: 3 | H6: BDA | I6: 100 | J6: 350 | K6: 200 | L6: 275 | M6: 0 | N6: 0 | O6: 0
A7: KC-10 | B7: A | C7: Australia | D7: EA-18 | E7: G | F7: itv | G7: 3 | H7: BDA | I7: 100 | J7: 350 | K7: 200 | L7: 275 | M7: 0 | N7: 0 | O7: 0
A8: KC-10 | B8: A | C8: Australia | D8: F-35 | E8: A | F8: itv | G8: 3 | H8: B | I8: 100 | J8: 300 | K8: 230 | L8: 350 | M8: 0 | N8: 0 | O8: 0
A9: KC-135 | B9: R | C9: Australia | D9: C-17 | E9: A | F9: itv | G9: 3 | H9: B | I9: 120 | J9: 310 | K9: 260 | L9: 270 | M9: 0 | N9: 0 | O9: 0
A10: KC-135 | B10: T | C10: Australia | D10: C-17 | E10: A | F10: itv | G10: 3 | H10: B | I10: 120 | J10: 310 | K10: 260 | L10: 270 | M10: 0 | N10: 0 | O10: 0
A11: KC-135 | B11: R | C11: Australia | D11: E-7 | E11: A | F11: itv | G11: 3 | H11: B | I11: 200 | J11: 300 | K11: 250 | L11: 290 | M11: 0 | N11: 0 | O11: 0
A12: KC-135 | B12: T | C12: Australia | D12: E-7 | E12: A | F12: itv | G12: 3 | H12: B | I12: 200 | J12: 300 | K12: 250 | L12: 290 | M12: 0 | N12: 0 | O12: 0
A13: KC-135 | B13: R | C13: Australia | D13: F/A-18 | E13: F | F13: itv | G13: 3 | H13: BDA | I13: 100 | J13: 285 | K13: 200 | L13: 275 | M13: 0 | N13: 0 | O13: 0
A14: KC-135 | B14: T | C14: Australia | D14: F/A-18 | E14: F | F14: itv | G14: 3 | H14: BDA | I14: 100 | J14: 285 | K14: 200 | L14: 275 | M14: 0 | N14: 0 | O14: 0
... A25: KC-46 | B25: A | C25: Australia | D25: C-17 | E25: A | F25: itv | G25: 1 | H25: B | I25: 200 | J25: 310 | K25: 250 | L25: 290 | M25: 0 | N25: 0 | O25: 0
A26: KC-46 | B26: A | C26: Australia | D26: F/A-18 | E26: F | F26: itv | G26: 3 | H26: BDA | I26: 50 | J26: 350 | K26: 180 | L26: 300 | M26: 0 | N26: 0 | O26: linear increase of minimum speed from 180 KCAS at FL200 to 255 KCAS at FL350
A27: KC-46 | B27: A | C27: Australia | D27: EA-18 | E27: G | F27: itv | G27: 3 | H27: BDA | I27: 50 | J27: 350 | K27: 180 | L27: 300 | M27: 0 | N27: 0 | O27: linear increase of minimum speed from 180 KCAS at FL200 to 255 KCAS at FL350
A28: KC-46 | B28: A | C28: Australia | D28: F/A-18 | E28: F | F28: itv | G28: 3 | H28: P | I28: 50 | J28: 350 | K28: 200 | L28: 300 | M28: 0 | N28: 0 | O28: linear increase of minimum speed from 200 KCAS at FL240 to 255 KCAS at FL350
A29: KC-46 | B29: A | C29: Australia | D29: EA-18 | E29: G | F29: itv | G29: 3 | H29: P | I29: 50 | J29: 350 | K29: 200 | L29: 300 | M29: 0 | N29: 0 | O29: linear increase of minimum speed from 200 KCAS at FL240 to 255 KCAS at FL350
A30: KC-46 | B30: A | C30: Australia | D30: F-35 | E30: A | F30: itv | G30: 2 | H30: B | I30: 100 | J30: 350 | K30: 265 | L30: 325 | M30: 0 | N30: 0 | O30: 0
