Workbook

Sheet Tankers
A1: nation | B1: type | C1: model
A2: {=_xlfn.UNIQUE(_xlfn._xlws.FILTER(Specifications!A2:C97, (Specifications!A2:A97<>"") * (Specifications!B2:B97<>"") * (Specifications!C2:C97<>"")))} -> Australia | B2: A330 MRTT | C2: KC-30A
A3: Omega | B3: KC-10 | C3: B
A4: Omega | B4: KDC-10 | C4: B
A5: Malaysia | B5: A400 | C5: M
A6: Singapore | B6: A330 MRTT | C6: A330 MRTT
A7: France | B7: A330 MRTT | C7: Phénix
A8: South Korea | B8: A330 MRTT | C8: KC-330
A9: MMF | B9: A330 MRTT | C9: KC-30M
A10: USA | B10: KC-135 | C10: R
A11: MSM | B11: KC-135 | C11: R
A12: USA | B12: KC-135 | C12: T
A13: USA | B13: KC-46 | C13: A
A14: France | B14: C-135 | C14: FR

Sheet Receivers
A1: nation | B1: type | C1: model
A2: {=_xlfn.UNIQUE(_xlfn._xlws.FILTER(Specifications!D2:F97, (Specifications!D2:D97<>"") * (Specifications!E2:E97<>"") * (Specifications!F2:F97<>"")))} -> Australia | B2: C-17 | C2: A
A3: Australia | B3: E-7 | C3: A
A4: Australia | B4: EA-18 | C4: G
A5: Australia | B5: F/A-18 | C5: A
A6: Australia | B6: F-35 | C6: A
A7: Australia | B7: A330 MRTT | C7: KC-30A
A8: Australia | B8: P-8 | C8: A
A9: USA | B9: B-1 | C9: B
A10: USA | B10: A-10 | C10: C
A11: Japan | B11: F-15 | C11: J
A12: Japan | B12: F-15 | C12: DJ
A13: Japan | B13: F-15 | C13: K
A14: Singapore | B14: F-15 | C14: SG
... A78: Australia | B78: F/A-18 | C78: F

Sheet Specifications
A1: tanker_nation | B1: tanker_type | C1: tanker_model | D1: receiver_nation | E1: receiver_type | F1: receiver_model | G1: c_tanker | H1: c_receiver | I1: vSRD_Tnkr | J1: vSRD_RCVR | K1: boom_pod_BDA | L1: min_alt | M1: max_alt | N1: min_as | O1: max_as_KCAS | P1: Max_as_M | Q1: fuel_flow_rate | R1: notes
A2: Australia | B2: A330 MRTT | C2: KC-30A | D2: Australia | E2: C-17 | F2: A | G2: 3 | H2: 3 | I2: July 2025 | J2: July 2025 | K2: B | L2: 150 | M2: 280 | N2: 265 | O2: 285 | P2: 0.8 | Q2: =3600*2.20462 -> 7936.632
A3: Australia | B3: A330 MRTT | C3: KC-30A | D3: Australia | E3: E-7 | F3: A | G3: 3 | H3: 3 | I3: July 2025 | J3: July 2025 | K3: B | L3: 200 | M3: 300 | N3: 250 | O3: 290 | P3: 0.72 | Q3: =1900*2.20462 -> 4188.778
A4: Australia | B4: A330 MRTT | C4: KC-30A | D4: Australia | E4: EA-18 | F4: G | G4: 3 | H4: 3 | I4: July 2025 | J4: July 2025 | K4: P | L4: 1500 ft AGL | M4: 350 | N4: 250 | O4: 300 | P4: 0.8 | Q4: =1200 * 2.20462 -> 2645.544 | R4: mininimum altitude in feet above ground level
A5: Australia | B5: A330 MRTT | C5: KC-30A | D5: Australia | E5: F/A-18 | F5: A | G5: 3 | H5: 3 | I5: July 2025 | J5: July 2025 | K5: P | L5: 1500 ft AGL | M5: 350 | N5: 250 | O5: 300 | P5: 0.8 | Q5: =1200 * 2.20462 -> 2645.544 | R5: mininimum altitude in feet above ground level
A6: Australia | B6: A330 MRTT | C6: KC-30A | D6: Australia | E6: F-35 | F6: A | G6: 3 | H6: 3 | I6: July 2025 | J6: July 2025 | K6: B | L6: 80 | M6: 350 | N6: 265 | O6: 325 | P6: 0.84 | Q6: =1000*2.20462 -> 2204.62
A7: Australia | B7: A330 MRTT | C7: KC-30A | D7: Australia | E7: A330 MRTT | F7: KC-30A | G7: 3 | H7: 3 | I7: July 2025 | J7: July 2025 | K7: B | L7: 150 | M7: 300 | N7: 250 | O7: 290 | P7: 0.8 | Q7: =3600*2.20462 -> 7936.632
A8: Australia | B8: A330 MRTT | C8: KC-30A | D8: Australia | E8: P-8 | F8: A | G8: 3 | H8: 3 | I8: July 2025 | J8: July 2025 | K8: B | L8: 80 | M8: 280 | N8: 250 | O8: 300 | P8: 0.76 | Q8: =1900*2.20462 -> 4188.778
A9: Australia | B9: A330 MRTT | C9: KC-30A | D9: USA | E9: B-1 | F9: B | G9: 3 | H9: 3 | I9: July 2025 | J9: July 2025 | K9: B | L9: 100 | M9: 270 | N9: 290 | O9: 315 | P9: 0.8 | Q9: =3600*2.20462 -> 7936.632
A10: Australia | B10: A330 MRTT | C10: KC-30A | D10: USA | E10: A-10 | F10: C | G10: 3 | H10: 3 | I10: July 2025 | J10: July 2025 | K10: B | L10: 100 | M10: 200 | N10: 190 | O10: 240 | P10: 0.46 | Q10: =1200*2.20462 -> 2645.544
A11: Australia | B11: A330 MRTT | C11: KC-30A | D11: Japan | E11: F-15 | F11: J | G11: 3 | H11: itv | I11: July 2025 | J11: itv | K11: B | L11: 100 | M11: 310 | N11: 265 | O11: 300 | P11: 0.8 | Q11: =1400*2.20462 -> 3086.468
A12: Australia | B12: A330 MRTT | C12: KC-30A | D12: Japan | E12: F-15 | F12: DJ | G12: 3 | H12: itv | I12: July 2025 | J12: itv | K12: B | L12: 100 | M12: 300 | N12: 265 | O12: 300 | P12: 0.77 | Q12: =1400*2.20462 -> 3086.468
A13: Australia | B13: A330 MRTT | C13: KC-30A | D13: Japan | E13: F-15 | F13: K | G13: 2 | H13: itv | I13: July 2025 | J13: itv | K13: B | L13: 100 | M13: 300 | N13: 265 | O13: 290 | P13: 0.8 | Q13: =1400*2.20462 -> 3086.468 | R13: For FL150-FL300 265 - 300 KCAS
A14: Australia | B14: A330 MRTT | C14: KC-30A | D14: Singapore | E14: F-15 | F14: SG | G14: 2 | H14: itv | I14: July 2025 | J14: itv | K14: B | L14: 100 | M14: 300 | N14: 265 | O14: 290 | P14: 0.78 | Q14: =1400*2.20462 -> 3086.468 | R14: For FL150-FL300 265 - 300 KCAS
A15: Australia | B15: A330 MRTT | C15: KC-30A | D15: Belgium | E15: F-16 | F15: A | G15: 3 | H15: itv | I15: July 2025 | J15: itv | K15: B | L15: 80 | M15: 300 | N15: 265 | O15: 315 | P15: 0.76 | Q15: =1400*2.20462 -> 3086.468
A16: Australia | B16: A330 MRTT | C16: KC-30A | D16: Denmark | E16: F-16 | F16: A | G16: 3 | H16: itv | I16: July 2025 | J16: itv | K16: B | L16: 80 | M16: 300 | N16: 265 | O16: 315 | P16: 0.76 | Q16: =1400*2.20462 -> 3086.468
A17: Australia | B17: A330 MRTT | C17: KC-30A | D17: Indonesia | E17: F-16 | F17: B | G17: 3 | H17: itv | I17: July 2025 | J17: itv | K17: B | L17: 80 | M17: 300 | N17: 265 | O17: 315 | P17: 0.76 | Q17: =1400*2.20462 -> 3086.468
A18: Australia | B18: A330 MRTT | C18: KC-30A | D18: Indonesia | E18: F-16 | F18: C | G18: 3 | H18: itv | I18: July 2025 | J18: itv | K18: B | L18: 80 | M18: 300 | N18: 265 | O18: 315 | P18: 0.76 | Q18: =1400*2.20462 -> 3086.468
A19: Australia | B19: A330 MRTT | C19: KC-30A | D19: Indonesia | E19: F-16 | F19: D | G19: 3 | H19: itv | I19: July 2025 | J19: itv | K19: B | L19: 80 | M19: 300 | N19: 265 | O19: 315 | P19: 0.76 | Q19: =1400*2.20462 -> 3086.468
A20: Australia | B20: A330 MRTT | C20: KC-30A | D20: Netherlands | E20: F-16 | F20: A | G20: 3 | H20: itv | I20: July 2025 | J20: itv | K20: B | L20: 80 | M20: 300 | N20: 265 | O20: 315 | P20: 0.76 | Q20: =1400*2.20462 -> 3086.468
A21: Australia | B21: A330 MRTT | C21: KC-30A | D21: Portugal | E21: F-16 | F21: A | G21: 3 | H21: itv | I21: July 2025 | J21: itv | K21: B | L21: 80 | M21: 300 | N21: 265 | O21: 315 | P21: 0.76 | Q21: =1400*2.20462 -> 3086.468
A22: Australia | B22: A330 MRTT | C22: KC-30A | D22: South Korea | E22: F-16 | F22: C | G22: 3 | H22: itv | I22: July 2025 | J22: itv | K22: B | L22: 80 | M22: 300 | N22: 265 | O22: 315 | P22: 0.76 | Q22: =1400*2.20462 -> 3086.468
A23: Australia | B23: A330 MRTT | C23: KC-30A | D23: Singapore | E23: F-16 | F23: C | G23: 3 | H23: itv | I23: July 2025 | J23: itv | K23: B | L23: 80 | M23: 300 | N23: 265 | O23: 315 | P23: 0.76 | Q23: =1400*2.20462 -> 3086.468
A24: Australia | B24: A330 MRTT | C24: KC-30A | D24: Singapore | E24: F-16 | F24: D | G24: 3 | H24: itv | I24: July 2025 | J24: itv | K24: B | L24: 80 | M24: 300 | N24: 265 | O24: 315 | P24: 0.76 | Q24: =1400*2.20462 -> 3086.468
A25: Australia | B25: A330 MRTT | C25: KC-30A | D25: Singapore | E25: F-16 | F25: D+ | G25: 3 | H25: itv | I25: July 2025 | J25: itv | K25: B | L25: 80 | M25: 300 | N25: 265 | O25: 315 | P25: 0.76 | Q25: =1400*2.20462 -> 3086.468
A26: Australia | B26: A330 MRTT | C26: KC-30A | D26: Thailand | E26: F-16 | F26: A | G26: 3 | H26: itv | I26: July 2025 | J26: itv | K26: B | L26: 80 | M26: 300 | N26: 265 | O26: 315 | P26: 0.76 | Q26: =1400*2.20462 -> 3086.468
... A29: Australia | B29: A330 MRTT | C29: KC-30A | D29: Japan | E29: F-2 | F29: B | G29: 3 | H29: itv | I29: July 2025 | J29: itv | K29: B | L29: 80 | M29: 320 | N29: 265 | O29: 315 | P29: 0.76 | Q29: =1400*2.20462 -> 3086.468
A30: Australia | B30: A330 MRTT | C30: KC-30A | D30: USA | E30: F-22 | F30: A | G30: 3 | H30: itv | I30: July 2025 | J30: itv | K30: B | L30: 80 | M30: 350 | N30: 270 | O30: 315 | P30: 0.82 | Q30: =800*2.20462 -> 1763.696
A31: Australia | B31: A330 MRTT | C31: KC-30A | D31: Italy | E31: F-35 | F31: A | G31: 3 | H31: itv | I31: July 2025 | J31: itv | K31: B | L31: 80 | M31: 350 | N31: 265 | O31: 325 | P31: 0.84 | Q31: =1000*2.20462 -> 2204.62
A32: Australia | B32: A330 MRTT | C32: KC-30A | D32: Japan | E32: F-35 | F32: A | G32: 3 | H32: itv | I32: July 2025 | J32: itv | K32: B | L32: 80 | M32: 350 | N32: 265 | O32: 325 | P32: 0.84 | Q32: =1000*2.20462 -> 2204.62
A33: Australia | B33: A330 MRTT | C33: KC-30A | D33: Denmark | E33: F-35 | F33: A | G33: 3 | H33: itv | I33: July 2025 | J33: itv | K33: B | L33: 80 | M33: 350 | N33: 265 | O33: 325 | P33: 0.84 | Q33: =1000*2.20462 -> 2204.62
A34: Australia | B34: A330 MRTT | C34: KC-30A | D34: Netherlands | E34: F-35 | F34: A | G34: 3 | H34: itv | I34: July 2025 | J34: itv | K34: B | L34: 80 | M34: 350 | N34: 265 | O34: 325 | P34: 0.84 | Q34: =1000*2.20462 -> 2204.62
A35: Australia | B35: A330 MRTT | C35: KC-30A | D35: Norway | E35: F-35 | F35: A | G35: 3 | H35: itv | I35: July 2025 | J35: itv | K35: B | L35: 80 | M35: 350 | N35: 265 | O35: 325 | P35: 0.84 | Q35: =1000*2.20462 -> 2204.62
A36: Australia | B36: A330 MRTT | C36: KC-30A | D36: South Korea | E36: F-35 | F36: A | G36: 3 | H36: itv | I36: July 2025 | J36: itv | K36: B | L36: 80 | M36: 350 | N36: 265 | O36: 325 | P36: 0.84 | Q36: =1000*2.20462 -> 2204.62
A37: Australia | B37: A330 MRTT | C37: KC-30A | D37: USA | E37: F-35 | F37: A | G37: 3 | H37: itv | I37: July 2025 | J37: itv | K37: B | L37: 80 | M37: 350 | N37: 265 | O37: 325 | P37: 0.84 | Q37: =1000*2.20462 -> 2204.62
A38: Australia | B38: A330 MRTT | C38: KC-30A | D38: Singapore | E38: A330 MRTT | F38: A-330 MRTT | G38: 3 | H38: itv | I38: July 2025 | J38: itv | K38: B | L38: 150 | M38: 300 | N38: 250 | O38: 290 | P38: 0.8 | Q38: =3600*2.20462 -> 7936.632
A39: Australia | B39: A330 MRTT | C39: KC-30A | D39: USA | E39: P-8 | F39: A | G39: 3 | H39: itv | I39: July 2025 | J39: itv | K39: B | L39: 80 | M39: 280 | N39: 250 | O39: 300 | P39: 0.76 | Q39: =1900*2.20462 -> 4188.778
A40: Australia | B40: A330 MRTT | C40: KC-30A | D40: USA | E40: B-2 | F40: A | G40: 3 | H40: itv | I40: July 2025 | J40: itv | K40: B | L40: 100 | M40: 270 | N40: 250 | O40: 270 | P40: 0.8 | Q40: =3600*2.20462 -> 7936.632
A41: Australia | B41: A330 MRTT | C41: KC-30A | D41: USA | E41: B-52 | F41: H | G41: 2 | H41: itv | I41: July 2025 | J41: itv | K41: B | L41: 150 | M41: 300 | N41: 250 | O41: 290 | P41: 0.8 | Q41: =2800*2.20462 -> 6172.936
A42: Australia | B42: A330 MRTT | C42: KC-30A | D42: USA | E42: C-17 | F42: A | G42: 3 | H42: itv | I42: July 2025 | J42: itv | K42: B | L42: 150 | M42: 280 | N42: 265 | O42: 285 | P42: 0.8 | Q42: =3600 *2.20462 -> 7936.632
...

Sheet Australia
A1: tanker_type | B1: tanker_model | C1: receiver_nation | D1: receiver_type | E1: receiver_model | F1: c_tanker | G1: c_receiver | H1: vSRD_Tnkr | I1: vSRD_RCVR | J1: boom_pod | K1: min_alt | L1: max_alt | M1: min_as | N1: max_as_KCAS | O1: Max_as_M | P1: fuel_flow_rate | Q1: notes
A2: {=_xlfn._xlws.FILTER(Specifications!B2:R100000, Specifications!A2:A100000 = "Australia", "")} -> A330 MRTT | B2: KC-30A | C2: Australia | D2: C-17 | E2: A | F2: 3 | G2: 3 | H2: July 2025 | I2: July 2025 | J2: B | K2: 150 | L2: 280 | M2: 265 | N2: 285 | O2: 0.8 | P2: 7936.632 | Q2: 0
A3: A330 MRTT | B3: KC-30A | C3: Australia | D3: E-7 | E3: A | F3: 3 | G3: 3 | H3: July 2025 | I3: July 2025 | J3: B | K3: 200 | L3: 300 | M3: 250 | N3: 290 | O3: 0.72 | P3: 4188.778 | Q3: 0
A4: A330 MRTT | B4: KC-30A | C4: Australia | D4: EA-18 | E4: G | F4: 3 | G4: 3 | H4: July 2025 | I4: July 2025 | J4: P | K4: 1500 ft AGL | L4: 350 | M4: 250 | N4: 300 | O4: 0.8 | P4: 2645.544 | Q4: mininimum altitude in feet above ground level
A5: A330 MRTT | B5: KC-30A | C5: Australia | D5: F/A-18 | E5: A | F5: 3 | G5: 3 | H5: July 2025 | I5: July 2025 | J5: P | K5: 1500 ft AGL | L5: 350 | M5: 250 | N5: 300 | O5: 0.8 | P5: 2645.544 | Q5: mininimum altitude in feet above ground level
A6: A330 MRTT | B6: KC-30A | C6: Australia | D6: F-35 | E6: A | F6: 3 | G6: 3 | H6: July 2025 | I6: July 2025 | J6: B | K6: 80 | L6: 350 | M6: 265 | N6: 325 | O6: 0.84 | P6: 2204.62 | Q6: 0
A7: A330 MRTT | B7: KC-30A | C7: Australia | D7: A330 MRTT | E7: KC-30A | F7: 3 | G7: 3 | H7: July 2025 | I7: July 2025 | J7: B | K7: 150 | L7: 300 | M7: 250 | N7: 290 | O7: 0.8 | P7: 7936.632 | Q7: 0
A8: A330 MRTT | B8: KC-30A | C8: Australia | D8: P-8 | E8: A | F8: 3 | G8: 3 | H8: July 2025 | I8: July 2025 | J8: B | K8: 80 | L8: 280 | M8: 250 | N8: 300 | O8: 0.76 | P8: 4188.778 | Q8: 0
A9: A330 MRTT | B9: KC-30A | C9: USA | D9: B-1 | E9: B | F9: 3 | G9: 3 | H9: July 2025 | I9: July 2025 | J9: B | K9: 100 | L9: 270 | M9: 290 | N9: 315 | O9: 0.8 | P9: 7936.632 | Q9: 0
A10: A330 MRTT | B10: KC-30A | C10: USA | D10: A-10 | E10: C | F10: 3 | G10: 3 | H10: July 2025 | I10: July 2025 | J10: B | K10: 100 | L10: 200 | M10: 190 | N10: 240 | O10: 0.46 | P10: 2645.544 | Q10: 0
A11: A330 MRTT | B11: KC-30A | C11: Japan | D11: F-15 | E11: J | F11: 3 | G11: itv | H11: July 2025 | I11: itv | J11: B | K11: 100 | L11: 310 | M11: 265 | N11: 300 | O11: 0.8 | P11: 3086.468 | Q11: 0
A12: A330 MRTT | B12: KC-30A | C12: Japan | D12: F-15 | E12: DJ | F12: 3 | G12: itv | H12: July 2025 | I12: itv | J12: B | K12: 100 | L12: 300 | M12: 265 | N12: 300 | O12: 0.77 | P12: 3086.468 | Q12: 0
A13: A330 MRTT | B13: KC-30A | C13: Japan | D13: F-15 | E13: K | F13: 2 | G13: itv | H13: July 2025 | I13: itv | J13: B | K13: 100 | L13: 300 | M13: 265 | N13: 290 | O13: 0.8 | P13: 3086.468 | Q13: For FL150-FL300 265 - 300 KCAS
A14: A330 MRTT | B14: KC-30A | C14: Singapore | D14: F-15 | E14: SG | F14: 2 | G14: itv | H14: July 2025 | I14: itv | J14: B | K14: 100 | L14: 300 | M14: 265 | N14: 290 | O14: 0.78 | P14: 3086.468 | Q14: For FL150-FL300 265 - 300 KCAS
A15: A330 MRTT | B15: KC-30A | C15: Belgium | D15: F-16 | E15: A | F15: 3 | G15: itv | H15: July 2025 | I15: itv | J15: B | K15: 80 | L15: 300 | M15: 265 | N15: 315 | O15: 0.76 | P15: 3086.468 | Q15: 0
A16: A330 MRTT | B16: KC-30A | C16: Denmark | D16: F-16 | E16: A | F16: 3 | G16: itv | H16: July 2025 | I16: itv | J16: B | K16: 80 | L16: 300 | M16: 265 | N16: 315 | O16: 0.76 | P16: 3086.468 | Q16: 0
A17: A330 MRTT | B17: KC-30A | C17: Indonesia | D17: F-16 | E17: B | F17: 3 | G17: itv | H17: July 2025 | I17: itv | J17: B | K17: 80 | L17: 300 | M17: 265 | N17: 315 | O17: 0.76 | P17: 3086.468 | Q17: 0
A18: A330 MRTT | B18: KC-30A | C18: Indonesia | D18: F-16 | E18: C | F18: 3 | G18: itv | H18: July 2025 | I18: itv | J18: B | K18: 80 | L18: 300 | M18: 265 | N18: 315 | O18: 0.76 | P18: 3086.468 | Q18: 0
A19: A330 MRTT | B19: KC-30A | C19: Indonesia | D19: F-16 | E19: D | F19: 3 | G19: itv | H19: July 2025 | I19: itv | J19: B | K19: 80 | L19: 300 | M19: 265 | N19: 315 | O19: 0.76 | P19: 3086.468 | Q19: 0
A20: A330 MRTT | B20: KC-30A | C20: Netherlands | D20: F-16 | E20: A | F20: 3 | G20: itv | H20: July 2025 | I20: itv | J20: B | K20: 80 | L20: 300 | M20: 265 | N20: 315 | O20: 0.76 | P20: 3086.468 | Q20: 0
A21: A330 MRTT | B21: KC-30A | C21: Portugal | D21: F-16 | E21: A | F21: 3 | G21: itv | H21: July 2025 | I21: itv | J21: B | K21: 80 | L21: 300 | M21: 265 | N21: 315 | O21: 0.76 | P21: 3086.468 | Q21: 0
A22: A330 MRTT | B22: KC-30A | C22: South Korea | D22: F-16 | E22: C | F22: 3 | G22: itv | H22: July 2025 | I22: itv | J22: B | K22: 80 | L22: 300 | M22: 265 | N22: 315 | O22: 0.76 | P22: 3086.468 | Q22: 0
A23: A330 MRTT | B23: KC-30A | C23: Singapore | D23: F-16 | E23: C | F23: 3 | G23: itv | H23: July 2025 | I23: itv | J23: B | K23: 80 | L23: 300 | M23: 265 | N23: 315 | O23: 0.76 | P23: 3086.468 | Q23: 0
A24: A330 MRTT | B24: KC-30A | C24: Singapore | D24: F-16 | E24: D | F24: 3 | G24: itv | H24: July 2025 | I24: itv | J24: B | K24: 80 | L24: 300 | M24: 265 | N24: 315 | O24: 0.76 | P24: 3086.468 | Q24: 0
A25: A330 MRTT | B25: KC-30A | C25: Singapore | D25: F-16 | E25: D+ | F25: 3 | G25: itv | H25: July 2025 | I25: itv | J25: B | K25: 80 | L25: 300 | M25: 265 | N25: 315 | O25: 0.76 | P25: 3086.468 | Q25: 0
A26: A330 MRTT | B26: KC-30A | C26: Thailand | D26: F-16 | E26: A | F26: 3 | G26: itv | H26: July 2025 | I26: itv | J26: B | K26: 80 | L26: 300 | M26: 265 | N26: 315 | O26: 0.76 | P26: 3086.468 | Q26: 0
... A77: A330 MRTT | B77: KC-30A | C77: India | D77: SU-30 | E77: MKI | F77: 2 | G77: itv | H77: July 2025 | I77: itv | J77: P | K77: 100 | L77: 320 | M77: 250 | N77: 300 | O77: 0.86 | P77: 1984.158 | Q77: 0

Sheet Canada
A1: tanker_type | B1: tanker_model | C1: receiver_nation | D1: receiver_type | E1: receiver_model | F1: c_tanker | G1: c_receiver | H1: vSRD_Tnkr | I1: vSRD_RCVR | J1: boom_pod | K1: min_alt | L1: max_alt | M1: min_as | N1: max_as_KCAS | O1: Max_as_M | P1: fuel_flow_rate | Q1: notes
A2: {=_xlfn._xlws.FILTER(Specifications!B2:R100000, Specifications!A2:A100000 = "Canada", "")} -> CC-150 | B2: T | C2: Australia | D2: F/A-18 | E2: F | F2: itv | G2: 3 | H2: itv | I2: July 2025 | J2: P | K2: 100 | L2: 250 | M2: 230 | N2: 270 | O2: 0 | P2: 0 | Q2: 0
A3: CC-150 | B3: T | C3: Australia | D3: EA-18 | E3: G | F3: itv | G3: 3 | H3: itv | I3: July 2025 | J3: P | K3: 100 | L3: 250 | M3: 230 | N3: 270 | O3: 0 | P3: 0 | Q3: 0

Sheet France
A1: tanker_type | B1: tanker_model | C1: receiver_nation | D1: receiver_type | E1: receiver_model | F1: c_tanker | G1: c_receiver | H1: vSRD_Tnkr | I1: vSRD_RCVR | J1: boom_pod | K1: min_alt | L1: max_alt | M1: min_as | N1: max_as_KCAS | O1: Max_as_M | P1: fuel_flow_rate | Q1: notes
A2: {=_xlfn._xlws.FILTER(Specifications!B2:R100000, Specifications!A2:A100000 = "France", "")} -> A330 MRTT | B2: Phénix | C2: Australia | D2: C-17 | E2: A | F2: itv | G2: 3 | H2: itv | I2: July 2025 | J2: B | K2: 150 | L2: 280 | M2: 265 | N2: 285 | O2: 0.8 | P2: 0 | Q2: 0
A3: A330 MRTT | B3: Phénix | C3: Australia | D3: E-7 | E3: A | F3: itv | G3: 3 | H3: itv | I3: July 2025 | J3: B | K3: 200 | L3: 300 | M3: 250 | N3: 290 | O3: 0.72 | P3: 0 | Q3: 0
A4: C-135 | B4: FR | C4: Australia | D4: E-7 | E4: A | F4: 3 | G4: 3 | H4: itv | I4: July 2025 | J4: B | K4: 200 | L4: 300 | M4: 250 | N4: 290 | O4: 0.72 | P4: 3000 | Q4: 0
A5: KC-135 | B5: RG | C5: Australia | D5: E-7 | E5: A | F5: 3 | G5: 3 | H5: itv | I5: July 2025 | J5: B | K5: 200 | L5: 300 | M5: 250 | N5: 290 | O5: 0.72 | P5: 3000 | Q5: 0
A6: A330 MRTT | B6: Phénix | C6: Australia | D6: EA-18 | E6: G | F6: itv | G6: 3 | H6: itv | I6: July 2025 | J6: P | K6: 15 | L6: 350 | M6: 250 | N6: 300 | O6: 0.8 | P6: 0 | Q6: given in 1500 ft
A7: A330 MRTT | B7: Phénix | C7: Australia | D7: F/A-18 | E7: F | F7: itv | G7: 3 | H7: itv | I7: July 2025 | J7: P | K7: 15 | L7: 350 | M7: 250 | N7: 300 | O7: 0.8 | P7: 0 | Q7: given in 1500 ft
A8: C-135 | B8: FR | C8: Australia | D8: F/A-18 | E8: F | F8: itv | G8: 3 | H8: itv | I8: July 2025 | J8: BDA | K8: 100 | L8: 285 | M8: 200 | N8: 275 | O8: 0 | P8: 0 | Q8: 0
A9: KC-135 | B9: RG | C9: Australia | D9: F/A-18 | E9: F | F9: itv | G9: 3 | H9: itv | I9: July 2025 | J9: BDA | K9: 100 | L9: 285 | M9: 200 | N9: 275 | O9: 0 | P9: 0 | Q9: 0
A10: C-135 | B10: FR | C10: Australia | D10: F/A-18 | E10: F | F10: itv | G10: 3 | H10: itv | I10: July 2025 | J10: P | K10: 100 | L10: 285 | M10: 200 | N10: 275 | O10: 0 | P10: 0 | Q10: 0
A11: C-135 | B11: FR | C11: Australia | D11: EA-18 | E11: G | F11: itv | G11: 3 | H11: itv | I11: July 2025 | J11: BDA | K11: 100 | L11: 285 | M11: 200 | N11: 275 | O11: 0 | P11: 0 | Q11: 0
A12: KC-135 | B12: RG | C12: Australia | D12: EA-18 | E12: G | F12: itv | G12: 3 | H12: itv | I12: July 2025 | J12: BDA | K12: 100 | L12: 285 | M12: 200 | N12: 275 | O12: 0 | P12: 0 | Q12: 0
A13: C-135 | B13: FR | C13: Australia | D13: EA-18 | E13: G | F13: itv | G13: 3 | H13: itv | I13: July 2025 | J13: P | K13: 100 | L13: 285 | M13: 200 | N13: 275 | O13: 0 | P13: 0 | Q13: 0
A14: A330 MRTT | B14: Phénix | C14: Australia | D14: F-35 | E14: A | F14: itv | G14: 3 | H14: itv | I14: July 2025 | J14: B | K14: 80 | L14: 350 | M14: 265 | N14: 325 | O14: 0.84 | P14: 0 | Q14: 0
A15: KC-135 | B15: RG | C15: Australia | D15: F-35 | E15: A | F15: itv | G15: 3 | H15: itv | I15: July 2025 | J15: B | K15: 80 | L15: 350 | M15: 265 | N15: 325 | O15: 0 | P15: 0 | Q15: 0
A16: A330 MRTT | B16: Phénix | C16: Australia | D16: A330 MRTT | E16: KC-30A | F16: itv | G16: 3 | H16: itv | I16: July 2025 | J16: B | K16: 150 | L16: 300 | M16: 250 | N16: 290 | O16: 0.8 | P16: 7936.632 | Q16: 0
A17: A330 MRTT | B17: Phénix | C17: Australia | D17: P-8 | E17: A | F17: itv | G17: 3 | H17: itv | I17: July 2025 | J17: B | K17: 80 | L17: 280 | M17: 250 | N17: 300 | O17: 0.76 | P17: 0 | Q17: 0
A18: C-135 | B18: FR | C18: Australia | D18: P-8 | E18: A | F18: itv | G18: 3 | H18: itv | I18: July 2025 | J18: B | K18: 80 | L18: 280 | M18: 250 | N18: 300 | O18: 0 | P18: 0 | Q18: 0
A19: KC-135 | B19: RG | C19: Australia | D19: P-8 | E19: A | F19: itv | G19: 3 | H19: itv | I19: July 2025 | J19: B | K19: 80 | L19: 280 | M19: 250 | N19: 300 | O19: 0 | P19: 0 | Q19: 0

Sheet Germany
A1: tanker_type | B1: tanker_model | C1: receiver_nation | D1: receiver_type | E1: receiver_model | F1: c_tanker | G1: c_receiver | H1: vSRD_Tnkr | I1: vSRD_RCVR | J1: boom_pod | K1: min_alt | L1: max_alt | M1: min_as | N1: max_as_KCAS | O1: Max_as_M | P1: fuel_flow_rate | Q1: notes
A2: {=_xlfn._xlws.FILTER(Specifications!B2:R100000, Specifications!A2:A100000 = "Germany", "")}

Sheet Italy
A1: tanker_type | B1: tanker_model | C1: receiver_nation | D1: receiver_type | E1: receiver_model | F1: c_tanker | G1: c_receiver | H1: vSRD_Tnkr | I1: vSRD_RCVR | J1: boom_pod | K1: min_alt | L1: max_alt | M1: min_as | N1: max_as_KCAS | O1: Max_as_M | P1: fuel_flow_rate | Q1: notes
A2: {=_xlfn._xlws.FILTER(Specifications!B2:R100000, Specifications!A2:A100000 = "Italy", "")} -> KC-130 | B2: J | C2: Australia | D2: F/A-18 | E2: F | F2: itv | G2: 3 | H2: itv | I2: July 2025 | J2: P | K2: 50 | L2: 250 | M2: 185 | N2: 250 | O2: 0 | P2: 0 | Q2: 0
A3: KC-130 | B3: J | C3: Australia | D3: EA-18 | E3: G | F3: itv | G3: 3 | H3: itv | I3: July 2025 | J3: P | K3: 50 | L3: 250 | M3: 185 | N3: 250 | O3: 0 | P3: 0 | Q3: 0
A4: KC-767 | B4: A | C4: Australia | D4: F/A-18 | E4: F | F4: itv | G4: 3 | H4: itv | I4: July 2025 | J4: BDA | K4: 150 | L4: 350 | M4: 225 | N4: 300 | O4: 0 | P4: 4005 | Q4: 0
A5: KC-767 | B5: A | C5: Australia | D5: EA-18 | E5: G | F5: itv | G5: 3 | H5: itv | I5: July 2025 | J5: BDA | K5: 150 | L5: 350 | M5: 225 | N5: 300 | O5: 0 | P5: 4005 | Q5: 0
A6: KC-767 | B6: A | C6: Australia | D6: F/A-18 | E6: F | F6: itv | G6: 3 | H6: itv | I6: July 2025 | J6: P | K6: 150 | L6: 350 | M6: 225 | N6: 300 | O6: 0 | P6: 2670 | Q6: 0
A7: KC-767 | B7: A | C7: Australia | D7: EA-18 | E7: G | F7: itv | G7: 3 | H7: itv | I7: July 2025 | J7: P | K7: 150 | L7: 350 | M7: 225 | N7: 300 | O7: 0 | P7: 2670 | Q7: 0
A8: KC-767 | B8: A | C8: Australia | D8: F-35 | E8: A | F8: itv | G8: 3 | H8: itv | I8: July 2025 | J8: B | K8: 100 | L8: 300 | M8: 265 | N8: 325 | O8: 0 | P8: 0 | Q8: 0

Sheet Japan
A1: tanker_type | B1: tanker_model | C1: receiver_nation | D1: receiver_type | E1: receiver_model | F1: c_tanker | G1: c_receiver | H1: vSRD_Tnkr | I1: vSRD_RCVR | J1: boom_pod | K1: min_alt | L1: max_alt | M1: min_as | N1: max_as_KCAS | O1: Max_as_M | P1: fuel_flow_rate | Q1: notes
A2: {=_xlfn._xlws.FILTER(Specifications!B2:R100000, Specifications!A2:A100000 = "Italy", "")} -> KC-130 | B2: J | C2: Australia | D2: F/A-18 | E2: F | F2: itv | G2: 3 | H2: itv | I2: July 2025 | J2: P | K2: 50 | L2: 250 | M2: 185 | N2: 250 | O2: 0 | P2: 0 | Q2: 0
A3: KC-130 | B3: J | C3: Australia | D3: EA-18 | E3: G | F3: itv | G3: 3 | H3: itv | I3: July 2025 | J3: P | K3: 50 | L3: 250 | M3: 185 | N3: 250 | O3: 0 | P3: 0 | Q3: 0
A4: KC-767 | B4: A | C4: Australia | D4: F/A-18 | E4: F | F4: itv | G4: 3 | H4: itv | I4: July 2025 | J4: BDA | K4: 150 | L4: 350 | M4: 225 | N4: 300 | O4: 0 | P4: 4005 | Q4: 0
A5: KC-767 | B5: A | C5: Australia | D5: EA-18 | E5: G | F5: itv | G5: 3 | H5: itv | I5: July 2025 | J5: BDA | K5: 150 | L5: 350 | M5: 225 | N5: 300 | O5: 0 | P5: 4005 | Q5: 0
A6: KC-767 | B6: A | C6: Australia | D6: F/A-18 | E6: F | F6: itv | G6: 3 | H6: itv | I6: July 2025 | J6: P | K6: 150 | L6: 350 | M6: 225 | N6: 300 | O6: 0 | P6: 2670 | Q6: 0
A7: KC-767 | B7: A | C7: Australia | D7: EA-18 | E7: G | F7: itv | G7: 3 | H7: itv | I7: July 2025 | J7: P | K7: 150 | L7: 350 | M7: 225 | N7: 300 | O7: 0 | P7: 2670 | Q7: 0
A8: KC-767 | B8: A | C8: Australia | D8: F-35 | E8: A | F8: itv | G8: 3 | H8: itv | I8: July 2025 | J8: B | K8: 100 | L8: 300 | M8: 265 | N8: 325 | O8: 0 | P8: 0 | Q8: 0

Sheet Malaysia
A1: tanker_type | B1: tanker_model | C1: receiver_nation | D1: receiver_type | E1: receiver_model | F1: c_tanker | G1: c_receiver | H1: vSRD_Tnkr | I1: vSRD_RCVR | J1: boom_pod | K1: min_alt | L1: max_alt | M1: min_as | N1: max_as_KCAS | O1: Max_as_M | P1: fuel_flow_rate | Q1: notes
A2: {=_xlfn._xlws.FILTER(Specifications!B2:R100000, Specifications!A2:A100000 = "Malaysia", "")} -> A400 | B2: M | C2: Australia | D2: F/A-18 | E2: F | F2: itv | G2: 1 | H2: itv | I2: July 2025 | J2: P | K2: 150 | L2: 250 | M2: 230 | N2: 270 | O2: 0 | P2: 0 | Q2: WDE (Wing Dispensing Equipment) Only
A3: A400 | B3: M | C3: Australia | D3: EA-18 | E3: G | F3: itv | G3: 1 | H3: itv | I3: July 2025 | J3: P | K3: 150 | L3: 250 | M3: 230 | N3: 270 | O3: 0 | P3: 0 | Q3: WDE (Wing Dispensing Equipment) Only

Sheet MMF
A1: tanker_type | B1: tanker_model | C1: receiver_nation | D1: receiver_type | E1: receiver_model | F1: c_tanker | G1: c_receiver | H1: vSRD_Tnkr | I1: vSRD_RCVR | J1: boom_pod | K1: min_alt | L1: max_alt | M1: min_as | N1: max_as_KCAS | O1: Max_as_M | P1: fuel_flow_rate | Q1: notes
A2: {=_xlfn._xlws.FILTER(Specifications!B2:R100000, Specifications!A2:A100000 = "MMF", "")} -> A330 MRTT | B2: KC-30M | C2: Australia | D2: C-17 | E2: A | F2: 2 | G2: 3 | H2: December 2025 | I2: July 2025 | J2: B | K2: 150 | L2: 280 | M2: 265 | N2: 285 | O2: 0.8 | P2: 7500 | Q2: 0
A3: A330 MRTT | B3: KC-30M | C3: Australia | D3: E-7 | E3: A | F3: 2 | G3: 3 | H3: December 2025 | I3: July 2025 | J3: B | K3: 200 | L3: 300 | M3: 250 | N3: 290 | O3: 0.72 | P3: 4200 | Q3: 0
A4: A330 MRTT | B4: KC-30M | C4: Australia | D4: EA-18 | E4: G | F4: 3 | G4: 3 | H4: December 2025 | I4: July 2025 | J4: P | K4: 150 | L4: 350 | M4: 250 | N4: 300 | O4: 0.8 | P4: 2425 | Q4: 0
A5: A330 MRTT | B5: KC-30M | C5: Australia | D5: F/A-18 | E5: F | F5: 3 | G5: 3 | H5: December 2025 | I5: July 2025 | J5: P | K5: 150 | L5: 350 | M5: 250 | N5: 300 | O5: 0.8 | P5: 2425 | Q5: 0
A6: A330 MRTT | B6: KC-30M | C6: Australia | D6: F-35 | E6: A | F6: 3 | G6: 3 | H6: December 2025 | I6: July 2025 | J6: B | K6: 80 | L6: 350 | M6: 265 | N6: 325 | O6: 0.84 | P6: 2200 | Q6: 0
A7: A330 MRTT | B7: KC-30M | C7: Australia | D7: A330 MRTT | E7: KC-30A | F7: N/A | G7: 3 | H7: December 2025 | I7: July 2025 | J7: B | K7: 150 | L7: 300 | M7: 250 | N7: 290 | O7: 0.8 | P7: 7936.632 | Q7: 0
A8: A330 MRTT | B8: KC-30M | C8: Australia | D8: P-8 | E8: A | F8: 3 | G8: 3 | H8: December 2025 | I8: July 2025 | J8: B | K8: 80 | L8: 280 | M8: 250 | N8: 300 | O8: 0.76 | P8: 4200 | Q8: 0
A9: A330 MRTT | B9: KC-30M | C9: USA | D9: B-1 | E9: B | F9: 3 | G9: itv | H9: December 2025 | I9: itv | J9: B | K9: 100 | L9: 270 | M9: 290 | N9: 310 | O9: 0.8 | P9: 2000 | Q9: 0
A10: A330 MRTT | B10: KC-30M | C10: USA | D10: B-2 | E10: A | F10: 2 | G10: itv | H10: December 2025 | I10: August 2025 | J10: B | K10: 100 | L10: 270 | M10: 250 | N10: 270 | O10: 0.76 | P10: 4400 | Q10: 0
A11: A330 MRTT | B11: KC-30M | C11: Bahrain | D11: F-16 | E11: C | F11: 3 | G11: itv | H11: December 2025 | I11: itv | J11: B | K11: 80 | L11: 350 | M11: 265 | N11: 315 | O11: 0.76 | P11: 3000 | Q11: No Conformal Fuel Tanks, No Raised Dorsal Spine.
A12: A330 MRTT | B12: KC-30M | C12: Belgium | D12: F-16 | E12: A | F12: 3 | G12: itv | H12: December 2025 | I12: itv | J12: B | K12: 80 | L12: 350 | M12: 265 | N12: 315 | O12: 0.76 | P12: 3000 | Q12: No Conformal Fuel Tanks, No Raised Dorsal Spine.
A13: A330 MRTT | B13: KC-30M | C13: Chile | D13: F-16 | E13: A | F13: 3 | G13: itv | H13: December 2025 | I13: itv | J13: B | K13: 80 | L13: 350 | M13: 265 | N13: 315 | O13: 0.76 | P13: 3000 | Q13: No Conformal Fuel Tanks, No Raised Dorsal Spine.
A14: A330 MRTT | B14: KC-30M | C14: Denmark | D14: F-16 | E14: A | F14: 3 | G14: itv | H14: December 2025 | I14: itv | J14: B | K14: 80 | L14: 350 | M14: 265 | N14: 315 | O14: 0.76 | P14: 3000 | Q14: No Conformal Fuel Tanks, No Raised Dorsal Spine.
A15: A330 MRTT | B15: KC-30M | C15: Egypt | D15: F-16 | E15: A | F15: 3 | G15: itv | H15: December 2025 | I15: itv | J15: B | K15: 80 | L15: 350 | M15: 265 | N15: 315 | O15: 0.76 | P15: 3000 | Q15: No Conformal Fuel Tanks, No Raised Dorsal Spine.
A16: A330 MRTT | B16: KC-30M | C16: Egypt | D16: F-16 | E16: C | F16: 3 | G16: itv | H16: December 2025 | I16: itv | J16: B | K16: 80 | L16: 350 | M16: 265 | N16: 315 | O16: 0.76 | P16: 3000 | Q16: No Conformal Fuel Tanks, No Raised Dorsal Spine.
A17: A330 MRTT | B17: KC-30M | C17: Greece | D17: F-16 | E17: C | F17: 3 | G17: itv | H17: December 2025 | I17: itv | J17: B | K17: 80 | L17: 350 | M17: 265 | N17: 315 | O17: 0.76 | P17: 3000 | Q17: No Conformal Fuel Tanks, No Raised Dorsal Spine.
A18: A330 MRTT | B18: KC-30M | C18: Iraq | D18: F-16 | E18: C | F18: 3 | G18: itv | H18: December 2025 | I18: itv | J18: B | K18: 80 | L18: 350 | M18: 265 | N18: 315 | O18: 0.76 | P18: 3000 | Q18: No Conformal Fuel Tanks, No Raised Dorsal Spine.
A19: A330 MRTT | B19: KC-30M | C19: Israel | D19: F-16 | E19: A | F19: 3 | G19: itv | H19: December 2025 | I19: itv | J19: B | K19: 80 | L19: 350 | M19: 265 | N19: 315 | O19: 0.76 | P19: 3000 | Q19: No Conformal Fuel Tanks, No Raised Dorsal Spine.
A20: A330 MRTT | B20: KC-30M | C20: Israel | D20: F-16 | E20: C | F20: 3 | G20: itv | H20: December 2025 | I20: itv | J20: B | K20: 80 | L20: 350 | M20: 265 | N20: 315 | O20: 0.76 | P20: 3000 | Q20: No Conformal Fuel Tanks, No Raised Dorsal Spine.
A21: A330 MRTT | B21: KC-30M | C21: Jordan | D21: F-16 | E21: A | F21: 3 | G21: itv | H21: December 2025 | I21: itv | J21: B | K21: 80 | L21: 350 | M21: 265 | N21: 315 | O21: 0.76 | P21: 3000 | Q21: No Conformal Fuel Tanks, No Raised Dorsal Spine.
A22: A330 MRTT | B22: KC-30M | C22: Korea | D22: F-16 | E22: C | F22: 3 | G22: itv | H22: December 2025 | I22: itv | J22: B | K22: 80 | L22: 350 | M22: 265 | N22: 315 | O22: 0.76 | P22: 3000 | Q22: No Conformal Fuel Tanks, No Raised Dorsal Spine.
... A45: A330 MRTT | B45: KC-30M | C45: USA | D45: F-16 | E45: D | F45: 3 | G45: itv | H45: December 2025 | I45: itv | J45: B | K45: 200 | L45: 350 | M45: 265 | N45: 315 | O45: 0.76 | P45: 3000 | Q45: No Conformal Fuel Tanks, No Raised Dorsal Spine.
A46: A330 MRTT | B46: KC-30M | C46: Belgium | D46: F-35 | E46: A | F46: 3 | G46: itv | H46: December 2025 | I46: itv | J46: B | K46: 80 | L46: 350 | M46: 265 | N46: 325 | O46: 0.84 | P46: 2200 | Q46: 0
A47: A330 MRTT | B47: KC-30M | C47: Denmark | D47: F-35 | E47: A | F47: 3 | G47: itv | H47: December 2025 | I47: itv | J47: B | K47: 80 | L47: 350 | M47: 265 | N47: 325 | O47: 0.84 | P47: 2200 | Q47: 0
A48: A330 MRTT | B48: KC-30M | C48: Italy | D48: F-35 | E48: A | F48: 3 | G48: itv | H48: December 2025 | I48: itv | J48: B | K48: 80 | L48: 350 | M48: 265 | N48: 325 | O48: 0.84 | P48: 2200 | Q48: 0
A49: A330 MRTT | B49: KC-30M | C49: Norway | D49: F-35 | E49: A | F49: 3 | G49: itv | H49: December 2025 | I49: itv | J49: B | K49: 80 | L49: 350 | M49: 265 | N49: 325 | O49: 0.84 | P49: 2200 | Q49: 0
A50: A330 MRTT | B50: KC-30M | C50: The Netherlands | D50: F-35 | E50: A | F50: 3 | G50: itv | H50: December 2025 | I50: itv | J50: B | K50: 80 | L50: 350 | M50: 265 | N50: 325 | O50: 0.84 | P50: 2200 | Q50: 0
A51: A330 MRTT | B51: KC-30M | C51: USA | D51: F-35 | E51: A | F51: 3 | G51: itv | H51: December 2025 | I51: itv | J51: B | K51: 80 | L51: 350 | M51: 265 | N51: 325 | O51: 0.84 | P51: 2200 | Q51: 0
A52: A330 MRTT | B52: KC-30M | C52: Italy | D52: F-35 | E52: B | F52: 3 | G52: itv | H52: December 2025 | I52: itv | J52: P | K52: 150 | L52: 350 | M52: 260 | N52: 300 | O52: 0.86 | P52: 1984 | Q52: 0
A53: A330 MRTT | B53: KC-30M | C53: UK | D53: F-35 | E53: B | F53: 3 | G53: itv | H53: December 2025 | I53: itv | J53: P | K53: 150 | L53: 350 | M53: 260 | N53: 300 | O53: 0.86 | P53: 1984 | Q53: 0
A54: A330 MRTT | B54: KC-30M | C54: USA | D54: F-35 | E54: B | F54: 3 | G54: itv | H54: December 2025 | I54: August 2025 | J54: P | K54: 150 | L54: 350 | M54: 260 | N54: 300 | O54: 0.86 | P54: 1984 | Q54: 0
A55: A330 MRTT | B55: KC-30M | C55: USA | D55: F-35 | E55: C | F55: 3 | G55: itv | H55: December 2025 | I55: August 2025 | J55: P | K55: 150 | L55: 350 | M55: 260 | N55: 300 | O55: 0.86 | P55: 1984 | Q55: 0
A56: A330 MRTT | B56: KC-30M | C56: USA | D56: F-22 | E56: A | F56: 3 | G56: itv | H56: December 2025 | I56: August 2025 | J56: B | K56: 80 | L56: 350 | M56: 270 | N56: 315 | O56: 0.82 | P56: 3000 | Q56: 0
A57: A330 MRTT | B57: KC-30M | C57: USA | D57: A-10 | E57: C | F57: 2 | G57: itv | H57: December 2025 | I57: August 2025 | J57: B | K57: 100 | L57: 180 | M57: 200 | N57: 220 | O57: 0.55 | P57: 3000 | Q57: 0
... A61: A330 MRTT | B61: KC-30M | C61: UK | D61: C-17 | E61: A | F61: 2 | G61: itv | H61: December 2025 | I61: itv | J61: B | K61: 150 | L61: 280 | M61: 265 | N61: 285 | O61: 0.8 | P61: 7500 | Q61: 0
A62: A330 MRTT | B62: KC-30M | C62: USA | D62: C-17 | E62: A | F62: 2 | G62: 2 | H62: December 2025 | I62: August 2025 | J62: B | K62: 150 | L62: 280 | M62: 265 | N62: 285 | O62: 0.8 | P62: 7500 | Q62: 0
A63: A330 MRTT | B63: KC-30M | C63: USA | D63: B-52 | E63: H | F63: 2 | G63: 2 | H63: December 2025 | I63: August 2025 | J63: B | K63: 150 | L63: 300 | M63: 250 | N63: 290 | O63: 0.8 | P63: 6300 | Q63: 0
A64: A330 MRTT | B64: KC-30M | C64: NATO | D64: E-3 | E64: A | F64: 2 | G64: N/A | H64: December 2025 | I64: N/A | J64: B | K64: 100 | L64: 290 | M64: 260 | N64: 280 | O64: 0.78 | P64: 5500 | Q64: 0
A65: A330 MRTT | B65: KC-30M | C65: Korea | D65: P-8 | E65: A | F65: 3 | G65: itv | H65: December 2025 | I65: itv | J65: B | K65: 80 | L65: 280 | M65: 250 | N65: 300 | O65: 0.76 | P65: 4200 | Q65: 0
...

Sheet MSM
A1: tanker_type | B1: tanker_model | C1: receiver_nation | D1: receiver_type | E1: receiver_model | F1: c_tanker | G1: c_receiver | H1: vSRD_Tnkr | I1: vSRD_RCVR | J1: boom_pod | K1: min_alt | L1: max_alt | M1: min_as | N1: max_as_KCAS | O1: Max_as_M | P1: fuel_flow_rate | Q1: notes
A2: {=_xlfn._xlws.FILTER(Specifications!B2:R100000, Specifications!A2:A100000 = "MSM", "")} -> KC-135 | B2: R | C2: Australia | D2: C-17 | E2: A | F2: itv | G2: 3 | H2: itv | I2: July 2025 | J2: B | K2: 120 | L2: 310 | M2: 260 | N2: 270 | O2: 0 | P2: 0 | Q2: 0
A3: KC-135 | B3: R | C3: Australia | D3: E-7 | E3: A | F3: 3 | G3: 3 | H3: itv | I3: July 2025 | J3: B | K3: 200 | L3: 300 | M3: 250 | N3: 290 | O3: 0.72 | P3: 3000 | Q3: 0
A4: KC-135 | B4: R | C4: Australia | D4: F/A-18 | E4: F | F4: itv | G4: 3 | H4: itv | I4: July 2025 | J4: BDA | K4: 50 | L4: 350 | M4: 200 | N4: 275 | O4: 0 | P4: 0 | Q4: 0
A5: KC-135 | B5: R | C5: Australia | D5: F/A-18 | E5: F | F5: itv | G5: 3 | H5: itv | I5: July 2025 | J5: P | K5: 50 | L5: 350 | M5: 220 | N5: 270 | O5: 0 | P5: 0 | Q5: 0
A6: KC-135 | B6: R | C6: Australia | D6: EA-18 | E6: G | F6: itv | G6: 3 | H6: itv | I6: July 2025 | J6: BDA | K6: 50 | L6: 350 | M6: 200 | N6: 275 | O6: 0 | P6: 0 | Q6: 0
A7: KC-135 | B7: R | C7: Australia | D7: EA-18 | E7: G | F7: itv | G7: 3 | H7: itv | I7: July 2025 | J7: P | K7: 50 | L7: 350 | M7: 220 | N7: 270 | O7: 0 | P7: 0 | Q7: 0
A8: KC-135 | B8: R | C8: Australia | D8: F-35 | E8: A | F8: itv | G8: 3 | H8: itv | I8: July 2025 | J8: B | K8: 100 | L8: 300 | M8: 230 | N8: 350 | O8: 0 | P8: 0 | Q8: 0
A9: KC-135 | B9: R | C9: Australia | D9: P-8 | E9: A | F9: itv | G9: 3 | H9: itv | I9: July 2025 | J9: B | K9: 80 | L9: 280 | M9: 250 | N9: 300 | O9: 0 | P9: 0 | Q9: 0

Sheet NATO
A1: tanker_type | B1: tanker_model | C1: receiver_nation | D1: receiver_type | E1: receiver_model | F1: c_tanker | G1: c_receiver | H1: vSRD_Tnkr | I1: vSRD_RCVR | J1: boom_pod | K1: min_alt | L1: max_alt | M1: min_as | N1: max_as_KCAS | O1: Max_as_M | P1: fuel_flow_rate | Q1: notes
A2: {=_xlfn._xlws.FILTER(Specifications!B2:R100000, Specifications!A2:A100000 = "Nato", "")}

Sheet Omega
A1: tanker_type | B1: tanker_model | C1: receiver_nation | D1: receiver_type | E1: receiver_model | F1: c_tanker | G1: c_receiver | H1: vSRD_Tnkr | I1: vSRD_RCVR | J1: boom_pod | K1: min_alt | L1: max_alt | M1: min_as | N1: max_as_KCAS | O1: Max_as_M | P1: fuel_flow_rate | Q1: notes
A2: {=_xlfn._xlws.FILTER(Specifications!B2:R100000, Specifications!A2:A100000 = "Omega", "")} -> KC-10 | B2: B | C2: Australia | D2: C-17 | E2: A | F2: itv | G2: 3 | H2: itv | I2: July 2025 | J2: B | K2: 120 | L2: 310 | M2: 275 | N2: 290 | O2: 0 | P2: 0 | Q2: 0
A3: KDC-10 | B3: B | C3: Australia | D3: E-7 | E3: A | F3: itv | G3: 0 | H3: itv | I3: July 2025 | J3: B | K3: 200 | L3: 320 | M3: 250 | N3: 290 | O3: 0.72 | P3: 0 | Q3: 0
A4: KC-10 | B4: A | C4: Australia | D4: F/A-18 | E4: F | F4: itv | G4: 3 | H4: itv | I4: July 2025 | J4: P | K4: 50 | L4: 330 | M4: 200 | N4: 300 | O4: 0 | P4: 0 | Q4: 0
A5: KC-10 | B5: A | C5: Australia | D5: EA-18 | E5: G | F5: itv | G5: 3 | H5: itv | I5: July 2025 | J5: P | K5: 50 | L5: 330 | M5: 200 | N5: 300 | O5: 0 | P5: 0 | Q5: 0
A6: KDC-10 | B6: B | C6: Australia | D6: F-35 | E6: A | F6: itv | G6: 3 | H6: itv | I6: July 2025 | J6: B | K6: 100 | L6: 300 | M6: 230 | N6: 350 | O6: 0 | P6: 0 | Q6: 0

Sheet Singapore
A1: tanker_type | B1: tanker_model | C1: receiver_nation | D1: receiver_type | E1: receiver_model | F1: c_tanker | G1: c_receiver | H1: vSRD_Tnkr | I1: vSRD_RCVR | J1: boom_pod | K1: min_alt | L1: max_alt | M1: min_as | N1: max_as_KCAS | O1: Max_as_M | P1: fuel_flow_rate | Q1: notes
A2: {=_xlfn._xlws.FILTER(Specifications!B2:R100000, Specifications!A2:A100000 = "Singapore", "")} -> A330 MRTT | B2: A330 MRTT | C2: Australia | D2: C-17 | E2: A | F2: itv | G2: 3 | H2: itv | I2: July 2025 | J2: B | K2: 150 | L2: 280 | M2: 265 | N2: 285 | O2: 0.8 | P2: 0 | Q2: 0
A3: A330 MRTT | B3: A330 MRTT | C3: Australia | D3: E-7 | E3: A | F3: itv | G3: 3 | H3: itv | I3: July 2025 | J3: B | K3: 200 | L3: 300 | M3: 250 | N3: 290 | O3: 0.72 | P3: 0 | Q3: 0
A4: A330 MRTT | B4: A330 MRTT | C4: Australia | D4: EA-18 | E4: G | F4: itv | G4: 3 | H4: itv | I4: July 2025 | J4: P | K4: 15 | L4: 350 | M4: 250 | N4: 300 | O4: 0.8 | P4: 0 | Q4: given in 1500 ft
A5: A330 MRTT | B5: A330 MRTT | C5: Australia | D5: F/A-18 | E5: F | F5: itv | G5: 3 | H5: itv | I5: July 2025 | J5: P | K5: 15 | L5: 350 | M5: 250 | N5: 300 | O5: 0.8 | P5: 0 | Q5: given in 1500 ft
A6: A330 MRTT | B6: A330 MRTT | C6: Australia | D6: F-35 | E6: A | F6: itv | G6: 3 | H6: itv | I6: July 2025 | J6: B | K6: 80 | L6: 350 | M6: 265 | N6: 325 | O6: 0.84 | P6: 0 | Q6: 0
A7: A330 MRTT | B7: A330 MRTT | C7: Australia | D7: A330 MRTT | E7: KC-30A | F7: itv | G7: 3 | H7: itv | I7: July 2025 | J7: B | K7: 150 | L7: 300 | M7: 250 | N7: 290 | O7: 0.8 | P7: 7936.632 | Q7: 0
A8: A330 MRTT | B8: A330 MRTT | C8: Australia | D8: P-8 | E8: A | F8: itv | G8: 3 | H8: itv | I8: July 2025 | J8: B | K8: 80 | L8: 280 | M8: 250 | N8: 300 | O8: 0.76 | P8: 0 | Q8: 0

Sheet South-Korea
A1: tanker_type | B1: tanker_model | C1: receiver_nation | D1: receiver_type | E1: receiver_model | F1: c_tanker | G1: c_receiver | H1: vSRD_Tnkr | I1: vSRD_RCVR | J1: boom_pod | K1: min_alt | L1: max_alt | M1: min_as | N1: max_as_KCAS | O1: Max_as_M | P1: fuel_flow_rate | Q1: notes
A2: {=_xlfn._xlws.FILTER(Specifications!B2:R100000, Specifications!A2:A100000 = "South Korea", "")} -> A330 MRTT | B2: KC-330 | C2: Australia | D2: C-17 | E2: A | F2: itv | G2: 3 | H2: itv | I2: July 2025 | J2: B | K2: 150 | L2: 280 | M2: 265 | N2: 285 | O2: 0.8 | P2: 0 | Q2: 0
A3: A330 MRTT | B3: KC-330 | C3: Australia | D3: E-7 | E3: A | F3: itv | G3: 3 | H3: itv | I3: July 2025 | J3: B | K3: 200 | L3: 300 | M3: 250 | N3: 290 | O3: 0.72 | P3: 0 | Q3: 0
A4: A330 MRTT | B4: KC-330 | C4: Australia | D4: EA-18 | E4: G | F4: itv | G4: 3 | H4: itv | I4: July 2025 | J4: P | K4: 15 | L4: 350 | M4: 250 | N4: 300 | O4: 0.8 | P4: 0 | Q4: given in 1500 ft
A5: A330 MRTT | B5: KC-330 | C5: Australia | D5: F/A-18 | E5: F | F5: itv | G5: 3 | H5: itv | I5: July 2025 | J5: P | K5: 15 | L5: 350 | M5: 250 | N5: 300 | O5: 0.8 | P5: 0 | Q5: given in 1500 ft
A6: A330 MRTT | B6: KC-330 | C6: Australia | D6: F-35 | E6: A | F6: itv | G6: 3 | H6: itv | I6: July 2025 | J6: B | K6: 80 | L6: 350 | M6: 265 | N6: 325 | O6: 0.84 | P6: 0 | Q6: 0
A7: A330 MRTT | B7: KC-330 | C7: Australia | D7: A330 MRTT | E7: KC-30A | F7: itv | G7: 3 | H7: itv | I7: July 2025 | J7: B | K7: 150 | L7: 300 | M7: 250 | N7: 290 | O7: 0.8 | P7: 7936.632 | Q7: 0
A8: A330 MRTT | B8: KC-330 | C8: Australia | D8: P-8 | E8: A | F8: itv | G8: 3 | H8: itv | I8: July 2025 | J8: B | K8: 80 | L8: 280 | M8: 250 | N8: 300 | O8: 0.76 | P8: 0 | Q8: 0

Sheet Spain
A1: tanker_type | B1: tanker_model | C1: receiver_nation | D1: receiver_type | E1: receiver_model | F1: c_tanker | G1: c_receiver | H1: vSRD_Tnkr | I1: vSRD_RCVR | J1: boom_pod | K1: min_alt | L1: max_alt | M1: min_as | N1: max_as_KCAS | O1: Max_as_M | P1: fuel_flow_rate | Q1: notes
A2: {=_xlfn._xlws.FILTER(Specifications!B2:R100000, Specifications!A2:A100000 = "Spain", "")}

Sheet Sweden
A1: tanker_type | B1: tanker_model | C1: receiver_nation | D1: receiver_type | E1: receiver_model | F1: c_tanker | G1: c_receiver | H1: vSRD_Tnkr | I1: vSRD_RCVR | J1: boom_pod | K1: min_alt | L1: max_alt | M1: min_as | N1: max_as_KCAS | O1: Max_as_M | P1: fuel_flow_rate | Q1: notes
A2: {=_xlfn._xlws.FILTER(Specifications!B2:R100000, Specifications!A2:A100000 = "Sweden", "")}

Sheet Turkey
A1: tanker_type | B1: tanker_model | C1: receiver_nation | D1: receiver_type | E1: receiver_model | F1: c_tanker | G1: c_receiver | H1: vSRD_Tnkr | I1: vSRD_RCVR | J1: boom_pod | K1: min_alt | L1: max_alt | M1: min_as | N1: max_as_KCAS | O1: Max_as_M | P1: fuel_flow_rate | Q1: notes
A2: {=_xlfn._xlws.FILTER(Specifications!B2:R100000, Specifications!A2:A100000 = "Turkey", "")}

Sheet UK
A1: tanker_type | B1: tanker_model | C1: receiver_nation | D1: receiver_type | E1: receiver_model | F1: c_tanker | G1: c_receiver | H1: vSRD_Tnkr | I1: vSRD_RCVR | J1: boom_pod | K1: min_alt | L1: max_alt | M1: min_as | N1: max_as_KCAS | O1: Max_as_M | P1: fuel_flow_rate | Q1: notes
A2: {=_xlfn._xlws.FILTER(Specifications!B2:R100000, Specifications!A2:A100000 = "UK", "")} -> A330 MRTT | B2: Voyager | C2: Australia | D2: EA-18 | E2: G | F2: itv | G2: 3 | H2: itv | I2: July 2025 | J2: P | K2: 15 | L2: 350 | M2: 250 | N2: 300 | O2: 0.8 | P2: 0 | Q2: given in 1500 ft
A3: A330 MRTT | B3: Voyager | C3: Australia | D3: F/A-18 | E3: F | F3: itv | G3: 3 | H3: itv | I3: July 2025 | J3: P | K3: 15 | L3: 350 | M3: 250 | N3: 300 | O3: 0.8 | P3: 0 | Q3: given in 1500 ft

Sheet USA
A1: tanker_type | B1: tanker_model | C1: receiver_nation | D1: receiver_type | E1: receiver_model | F1: c_tanker | G1: c_receiver | H1: vSRD_Tnkr | I1: vSRD_RCVR | J1: boom_pod | K1: min_alt | L1: max_alt | M1: min_as | N1: max_as_KCAS | O1: Max_as_M | P1: fuel_flow_rate | Q1: notes
A2: {=_xlfn._xlws.FILTER(Specifications!B2:R100000, Specifications!A2:A100000 = "USA", "")} -> KC-135 | B2: R | C2: Australia | D2: C-17 | E2: A | F2: itv | G2: 3 | H2: itv | I2: July 2025 | J2: B | K2: 120 | L2: 310 | M2: 260 | N2: 270 | O2: 0 | P2: 0 | Q2: 0
A3: KC-135 | B3: T | C3: Australia | D3: C-17 | E3: A | F3: itv | G3: 3 | H3: itv | I3: July 2025 | J3: B | K3: 120 | L3: 310 | M3: 260 | N3: 270 | O3: 0 | P3: 0 | Q3: 0
A4: KC-46 | B4: A | C4: Australia | D4: C-17 | E4: A | F4: itv | G4: 1 | H4: itv | I4: July 2025 | J4: B | K4: 200 | L4: 310 | M4: 250 | N4: 290 | O4: 0 | P4: 0 | Q4: 0
A5: KC-135 | B5: R | C5: Australia | D5: E-7 | E5: A | F5: 3 | G5: 3 | H5: August 2025 | I5: July 2025 | J5: B | K5: 200 | L5: 300 | M5: 250 | N5: 290 | O5: 0.72 | P5: 3000 | Q5: 0
A6: KC-135 | B6: T | C6: Australia | D6: E-7 | E6: A | F6: 3 | G6: 3 | H6: August 2025 | I6: July 2025 | J6: B | K6: 200 | L6: 300 | M6: 250 | N6: 290 | O6: 0.72 | P6: 3000 | Q6: 0
A7: KC-130 | B7: J | C7: Australia | D7: F/A-18 | E7: F | F7: itv | G7: 3 | H7: itv | I7: July 2025 | J7: P | K7: 50 | L7: 350 | M7: 185 | N7: 250 | O7: 0 | P7: 0 | Q7: USMC
A8: KC-130 | B8: J | C8: Australia | D8: EA-18 | E8: G | F8: itv | G8: 3 | H8: itv | I8: July 2025 | J8: P | K8: 50 | L8: 350 | M8: 185 | N8: 250 | O8: 0 | P8: 0 | Q8: USMC
A9: KC-135 | B9: R | C9: Australia | D9: F/A-18 | E9: F | F9: itv | G9: 3 | H9: itv | I9: July 2025 | J9: BDA | K9: 100 | L9: 285 | M9: 200 | N9: 275 | O9: 0 | P9: 0 | Q9: 0
A10: KC-135 | B10: T | C10: Australia | D10: F/A-18 | E10: F | F10: itv | G10: 3 | H10: itv | I10: July 2025 | J10: BDA | K10: 100 | L10: 285 | M10: 200 | N10: 275 | O10: 0 | P10: 0 | Q10: 0
A11: KC-135 | B11: R | C11: Australia | D11: F/A-18 | E11: F | F11: itv | G11: 3 | H11: itv | I11: July 2025 | J11: P | K11: 100 | L11: 350 | M11: 220 | N11: 300 | O11: 0 | P11: 0 | Q11: 0
A12: KC-135 | B12: T | C12: Australia | D12: F/A-18 | E12: F | F12: itv | G12: 3 | H12: itv | I12: July 2025 | J12: P | K12: 100 | L12: 350 | M12: 220 | N12: 300 | O12: 0 | P12: 0 | Q12: 0
A13: KC-135 | B13: R | C13: Australia | D13: EA-18 | E13: G | F13: itv | G13: 3 | H13: itv | I13: July 2025 | J13: BDA | K13: 100 | L13: 285 | M13: 200 | N13: 275 | O13: 0 | P13: 0 | Q13: 0
A14: KC-135 | B14: T | C14: Australia | D14: EA-18 | E14: G | F14: itv | G14: 3 | H14: itv | I14: July 2025 | J14: BDA | K14: 100 | L14: 285 | M14: 200 | N14: 275 | O14: 0 | P14: 0 | Q14: 0
A15: KC-135 | B15: R | C15: Australia | D15: EA-18 | E15: G | F15: itv | G15: 3 | H15: itv | I15: July 2025 | J15: P | K15: 100 | L15: 350 | M15: 220 | N15: 300 | O15: 0 | P15: 0 | Q15: 0
A16: KC-135 | B16: T | C16: Australia | D16: EA-18 | E16: G | F16: itv | G16: 3 | H16: itv | I16: July 2025 | J16: P | K16: 100 | L16: 350 | M16: 220 | N16: 300 | O16: 0 | P16: 0 | Q16: 0
A17: KC-46 | B17: A | C17: Australia | D17: F/A-18 | E17: F | F17: itv | G17: 3 | H17: itv | I17: July 2025 | J17: BDA | K17: 50 | L17: 350 | M17: 180 | N17: 300 | O17: 0 | P17: 0 | Q17: 0
A18: KC-46 | B18: A | C18: Australia | D18: EA-18 | E18: G | F18: itv | G18: 3 | H18: itv | I18: July 2025 | J18: BDA | K18: 50 | L18: 350 | M18: 180 | N18: 300 | O18: 0 | P18: 0 | Q18: 0
A19: KC-46 | B19: A | C19: Australia | D19: F/A-18 | E19: F | F19: itv | G19: 3 | H19: itv | I19: July 2025 | J19: P | K19: 50 | L19: 350 | M19: 200 | N19: 300 | O19: 0 | P19: 0 | Q19: 0
A20: KC-46 | B20: A | C20: Australia | D20: EA-18 | E20: G | F20: itv | G20: 3 | H20: itv | I20: July 2025 | J20: P | K20: 50 | L20: 350 | M20: 200 | N20: 300 | O20: 0 | P20: 0 | Q20: 0
... A25: KC-135 | B25: T | C25: Australia | D25: P-8 | E25: A | F25: itv | G25: 3 | H25: itv | I25: July 2025 | J25: B | K25: 80 | L25: 280 | M25: 250 | N25: 300 | O25: 0 | P25: 0 | Q25: 0
A26: KC-135 | B26: R | C26: USA | D26: A-10 | E26: A | F26: 3 | G26: 3 | H26: August 2025 | I26: August 2025 | J26: B | K26: 0 | L26: 150 | M26: 210 | N26: 230 | O26: 0.55 | P26: 2400 | Q26: 0
A27: KC-135 | B27: R | C27: USA | D27: A-10 | E27: C | F27: 3 | G27: 3 | H27: August 2025 | I27: August 2025 | J27: B | K27: 0 | L27: 150 | M27: 210 | N27: 230 | O27: 0.55 | P27: 2400 | Q27: 0
A28: KC-135 | B28: R | C28: USA | D28: B-1 | E28: B | F28: 3 | G28: 3 | H28: August 2025 | I28: August 2025 | J28: B | K28: 180 | L28: 300 | M28: 270 | N28: 325 | O28: 0.8 | P28: 7000 | Q28: 0
A29: KC-135 | B29: R | C29: USA | D29: B-2 | E29: A | F29: 3 | G29: 3 | H29: August 2025 | I29: August 2025 | J29: B | K29: 100 | L29: 310 | M29: 250 | N29: 280 | O29: 0.76 | P29: 5200 | Q29: 0
A30: KC-135 | B30: R | C30: USA | D30: B-52 | E30: H | F30: 3 | G30: 3 | H30: August 2025 | I30: August 2025 | J30: B | K30: 150 | L30: 350 | M30: 250 | N30: 290 | O30: 0.8 | P30: 6500 | Q30: 0
A31: KC-135 | B31: R | C31: USA | D31: C-5 | E31: M | F31: 3 | G31: 3 | H31: August 2025 | I31: August 2025 | J31: B | K31: 180 | L31: 300 | M31: 250 | N31: 275 | O31: 0.77 | P31: 6800 | Q31: 0
A32: KC-135 | B32: R | C32: USA | D32: C-17 | E32: A | F32: 3 | G32: 3 | H32: August 2025 | I32: August 2025 | J32: B | K32: 50 | L32: 310 | M32: 250 | N32: 295 | O32: 0.77 | P32: 6800 | Q32: 0
A33: KC-135 | B33: R | C33: USA | D33: C-32 | E33: B | F33: 3 | G33: 3 | H33: August 2025 | I33: August 2025 | J33: B | K33: 150 | L33: 300 | M33: 260 | N33: 290 | O33: 0.84 | P33: 6000 | Q33: 0
A34: KC-135 | B34: R | C34: USA | D34: C-130 | E34: E | F34: 3 | G34: 3 | H34: August 2025 | I34: August 2025 | J34: B | K34: 50 | L34: 160 | M34: 180 | N34: 220 | O34: 0.9 | P34: 3800 | Q34: 0
A35: KC-135 | B35: R | C35: USA | D35: C-130 | E35: H | F35: 3 | G35: 3 | H35: August 2025 | I35: August 2025 | J35: B | K35: 50 | L35: 160 | M35: 180 | N35: 220 | O35: 0.9 | P35: 3800 | Q35: 0
A36: KC-135 | B36: R | C36: USA | D36: C-130 | E36: P | F36: 3 | G36: 3 | H36: August 2025 | I36: August 2025 | J36: B | K36: 50 | L36: 160 | M36: 180 | N36: 220 | O36: 0.9 | P36: 3800 | Q36: 0
A37: KC-135 | B37: R | C37: USA | D37: C-130 | E37: U | F37: 3 | G37: 3 | H37: August 2025 | I37: August 2025 | J37: B | K37: 50 | L37: 160 | M37: 180 | N37: 220 | O37: 0.9 | P37: 3800 | Q37: 0
... A74: KC-135 | B74: R | C74: Japan | D74: F-15 | E74: J | F74: 3 | G74: 3 | H74: August 2025 | I74: March 2025 | J74: B | K74: 80 | L74: 350 | M74: 275 | N74: 325 | O74: 0.84 | P74: 3400 | Q74: 0
A75: KC-135 | B75: R | C75: Korea | D75: F-15 | E75: K | F75: 3 | G75: 3 | H75: August 2025 | I75: itv | J75: B | K75: itv | L75: itv | M75: itv | N75: itv | O75: itv | P75: 3400 | Q75: 0
A76: KC-135 | B76: R | C76: Japan | D76: F-15 | E76: DJ | F76: 3 | G76: 3 | H76: August 2025 | I76: March 2025 | J76: B | K76: 80 | L76: 350 | M76: 275 | N76: 325 | O76: 0.84 | P76: 3400 | Q76: 0
A77: KC-135 | B77: R | C77: Saudi Arabia | D77: F-15 | E77: S | F77: 3 | G77: N/A | H77: August 2025 | I77: N/A | J77: B | K77: N/A | L77: N/A | M77: N/A | N77: N/A | O77: N/A | P77: 3400 | Q77: 0
A78: KC-135 | B78: R | C78: Saudi Arabia | D78: F-15 | E78: SA | F78: 3 | G78: N/A | H78: August 2025 | I78: N/A | J78: B | K78: N/A | L78: N/A | M78: N/A | N78: N/A | O78: N/A | P78: 3400 | Q78: 0
A79: KC-135 | B79: R | C79: Singapore | D79: F-15 | E79: SG | F79: 3 | G79: 3 | H79: August 2025 | I79: itv | J79: B | K79: itv | L79: itv | M79: itv | N79: itv | O79: itv | P79: 3400 | Q79: 0
A80: KC-135 | B80: R | C80: Qatar | D80: F-15 | E80: QA | F80: 3 | G80: N/A | H80: August 2025 | I80: N/A | J80: B | K80: N/A | L80: N/A | M80: N/A | N80: N/A | O80: N/A | P80: 3400 | Q80: 0
...
